Workbook
Name A_F: mortality!$B$3
Name A_F: 'P01'!$B$29
Name A_F: 'P02'!$B$29
Name A_F: 'P03'!$B$29
Name A_F: 'P04'!$B$29
Name A_F: 'P05'!$B$29
Name A_F: 'P06'!$B$29
Name A_F: 'P07'!$B$29
Name A_F: 'P08'!$B$29
Name A_F: 'P09'!$B$29
Name A_F: 'P10'!$B$29
Name A_M: mortality!$B$2
Name A_M: 'P01'!$B$28
Name A_M: 'P02'!$B$28
Name A_M: 'P03'!$B$28
Name A_M: 'P04'!$B$28
Name A_M: 'P05'!$B$28
Name A_M: 'P06'!$B$28
Name A_M: 'P07'!$B$28
Name A_M: 'P08'!$B$28
Name A_M: 'P09'!$B$28
Name A_M: 'P10'!$B$28
Name age_at_entry: 'P01'!$B$14
Name age_at_entry: 'P02'!$B$14
Name age_at_entry: 'P03'!$B$14
Name age_at_entry: 'P04'!$B$14
Name age_at_entry: 'P05'!$B$14
Name age_at_entry: 'P06'!$B$14
Name age_at_entry: 'P07'!$B$14
Name age_at_entry: 'P08'!$B$14
Name age_at_entry: 'P09'!$B$14
Name age_at_entry: 'P10'!$B$14
Name all_ok: summary!$B$28
Name B_F: mortality!$B$5
Name B_F: 'P01'!$B$31
Name B_F: 'P02'!$B$31
Name B_F: 'P03'!$B$31
Name B_F: 'P04'!$B$31
Name B_F: 'P05'!$B$31
Name B_F: 'P06'!$B$31
Name B_F: 'P07'!$B$31
Name B_F: 'P08'!$B$31
Name B_F: 'P09'!$B$31
Name B_F: 'P10'!$B$31
Name B_M: mortality!$B$4
Name B_M: 'P01'!$B$30
Name B_M: 'P02'!$B$30
Name B_M: 'P03'!$B$30
Name B_M: 'P04'!$B$30
Name B_M: 'P05'!$B$30
Name B_M: 'P06'!$B$30
Name B_M: 'P07'!$B$30
Name B_M: 'P08'!$B$30
Name B_M: 'P09'!$B$30
Name B_M: 'P10'!$B$30
Name birth_date: 'P01'!$B$5
Name birth_date: 'P02'!$B$5
Name birth_date: 'P03'!$B$5
Name birth_date: 'P04'!$B$5
Name birth_date: 'P05'!$B$5

Sheet readme
A1: Halley term assurance: reference workbook for docs/spec/term-assurance.md (version 0.1).
A2: Built from the specification alone: typed cells are its reference inputs (sections 3.3, 6, 13); every other cell is a formula transcribing one formula of the spec.
A4: Sheets
A5: mortality: the 6.1 parameters A and B by sex and c, and the mortality table q_ann(sex, x) materialised for ages 18 to 120 from the 6.1 formula in its stated order (section 11, materialised-block option). The one block shared by the policy sheets: each q_ann cell looks it up by INDEX/MATCH on (sex, age).
A6: P01 .. P10: one sheet per policy, named by policy_id, with the section 11 blocks in order from the top: inputs (3.1, plus the run-level valuation_date of 3.3), typed; derived constants (3.2, 4.3, 5) by formula; basis constants (6) with i_m, v_m, e_m by formula; lapse table (6.2); commission table (6.6); the monthly block (7.1, 11.1) with a header row and rows t = 0 .. rem_m, the row checks of section 12 to its right; scalars (11.2); check cells (12). Every formula reads this sheet's own cells, through sheet-scoped defined names (sex, premium, rem_m, i_m, lapse_table, scale_money, ...) or same-sheet absolute references, except the q_ann lookup on mortality.
A7: summary: the 11.2 scalars per policy by reference, the 11.3 scalar totals in the row labelled total (plain SUMs in ascending policy_id order), the <id>_ok cells per policy by reference with ok per policy and all_ok (defined name all_ok), and the 11.3 totals by t = 0 .. 480 over the ten policies, policies beyond their own rem_m read as zero.
A9: Conventions
A10: q_ann is looked up from the materialised (sex, age, q_ann) block on mortality, ages 18 to 120, each cell the section 6.1 formula in its stated order (section 11 option 2); the 6.1 parameters are typed on mortality (the table reads them) and on every policy sheet (the basis block of section 11).
A11: Row t = 0 holds the state variables only (pols_if, infl, disc, reserve, reserve_pp, reserve_floored); month quantities are blank there (section 4.1).
A12: Tolerance (section 1): |a - b| <= 1e-9 * max(|a|, |b|, scale); inequalities use a <= b + 1e-9 * scale; 'exactly' is a plain = comparison. The scales are the check block's scale_money, scale_pp and scale_count, from the sheet's own inputs.
A13: P7 and P11 are engine-only (rows beyond rem_m, batch independence) and have no cell.
A14: The spec's c is the defined name gm_c because Excel reserves the names R and C.
... A17: Policy sheet blocks (block, rows; column A label or t, B value, C section, D unit)
A18: inputs (3.1, 3.3), typed | B18: 2 to 11
A19: derived constants (3.2, 4.3, 5), by formula | B19: 14 to 20
A20: basis constants (6), i_m, v_m, e_m by formula | B20: 23 to 34
A21: lapse table (6.2) | B21: 38 to 43
A22: commission table (6.6) | B22: 47 to 48
A23: monthly block (7.1, 11.1) and row checks (12) | B23: header 51; row of t is 52 + t
A24: scalars (11.2) | B24: from 55 + rem_m
A25: check cells (12): scales and helpers, then <id>_ok, rows_ok, ok | B25: from 74 + rem_m; <id>_ok from 80 + rem_m
A27: Policy sheet monthly columns (symbol, unit, spec section)
A28: t | B28: Int | C28: 4.1
A29: dur_y | B29: Int | C29: 5
A30: age | B30: Int | C30: 5
A31: q_ann | B31: Prob annual | C31: 6.1
A32: q_m | B32: Prob monthly | C32: 6.1
A33: w_ann | B33: Prob annual | C33: 6.2
A34: w_m | B34: Prob monthly | C34: 6.2
A35: comm_rate | B35: Fraction | C35: 6.6
A36: infl | B36: factor (state; infl(0) = 1) | C36: 6.4
A37: deaths | B37: Count | C37: 7.3
A38: lapses | B38: Count | C38: 7.3
A39: maturities | B39: Count | C39: 7.3
... A62: reserve_floored | B62: Money (state) | C62: 10.5
A64: Policy sheet row check columns (section 12)
A65: H1 | B65: pols_if >= 0 and non-increasing, exactly (t = 0 .. rem_m)
A66: H2 | B66: rates in [0, 1] exactly; deaths + lapses + maturities <= pols_if(t-1) within tolerance
A67: H4_lhs | B67: helper: roll-forward left-hand side
A68: H4 | B68: roll-forward equals reserve(t) within tolerance
...

Sheet mortality
A1: Mortality parameters (section 6.1), each in one cell: the table below reads these
A2: A_M | B2: 0.0002 | C2: 6.1 | D2: Gompertz-Makeham A, sex M
A3: A_F | B3: 0.00015 | C3: 6.1 | D3: Gompertz-Makeham A, sex F
A4: B_M | B4: 1.7e-05 | C4: 6.1 | D4: Gompertz-Makeham B, sex M
A5: B_F | B5: 1.1e-05 | C5: 6.1 | D5: Gompertz-Makeham B, sex F
A6: c | B6: 1.1 | C6: 6.1 | D6: Gompertz-Makeham c (both sexes); defined name gm_c
A8: Mortality table q_ann(sex, x) (section 6.1): 1 - exp(-(A + B * c^x * (c - 1) / ln(c))), ages 18 to 120; shared by every policy sheet, which looks it up by (sex, age)
A9: x | B9: M | C9: F
A10: 18 | B10: =1-EXP(-(A_M+B_M*gm_c^$A10*(gm_c-1)/LN(gm_c))) -> 0.00029912472 | C10: =1-EXP(-(A_F+B_F*gm_c^$A10*(gm_c-1)/LN(gm_c))) -> 0.00021414554
A11: 19 | B11: =1-EXP(-(A_M+B_M*gm_c^$A11*(gm_c-1)/LN(gm_c))) -> 0.00030903865 | C11: =1-EXP(-(A_F+B_F*gm_c^$A11*(gm_c-1)/LN(gm_c))) -> 0.000220561
A12: 20 | B12: =1-EXP(-(A_M+B_M*gm_c^$A12*(gm_c-1)/LN(gm_c))) -> 0.00031994386 | C12: =1-EXP(-(A_F+B_F*gm_c^$A12*(gm_c-1)/LN(gm_c))) -> 0.00022761795
A13: 21 | B13: =1-EXP(-(A_M+B_M*gm_c^$A13*(gm_c-1)/LN(gm_c))) -> 0.00033193945 | C13: =1-EXP(-(A_F+B_F*gm_c^$A13*(gm_c-1)/LN(gm_c))) -> 0.00023538054
A14: 22 | B14: =1-EXP(-(A_M+B_M*gm_c^$A14*(gm_c-1)/LN(gm_c))) -> 0.00034513444 | C14: =1-EXP(-(A_F+B_F*gm_c^$A14*(gm_c-1)/LN(gm_c))) -> 0.00024391931
A15: 23 | B15: =1-EXP(-(A_M+B_M*gm_c^$A15*(gm_c-1)/LN(gm_c))) -> 0.00035964872 | C15: =1-EXP(-(A_F+B_F*gm_c^$A15*(gm_c-1)/LN(gm_c))) -> 0.00025331188
A16: 24 | B16: =1-EXP(-(A_M+B_M*gm_c^$A16*(gm_c-1)/LN(gm_c))) -> 0.00037561419 | C16: =1-EXP(-(A_F+B_F*gm_c^$A16*(gm_c-1)/LN(gm_c))) -> 0.00026364361
A17: 25 | B17: =1-EXP(-(A_M+B_M*gm_c^$A17*(gm_c-1)/LN(gm_c))) -> 0.00039317592 | C17: =1-EXP(-(A_F+B_F*gm_c^$A17*(gm_c-1)/LN(gm_c))) -> 0.00027500839
A18: 26 | B18: =1-EXP(-(A_M+B_M*gm_c^$A18*(gm_c-1)/LN(gm_c))) -> 0.00041249345 | C18: =1-EXP(-(A_F+B_F*gm_c^$A18*(gm_c-1)/LN(gm_c))) -> 0.00028750949
A19: 27 | B19: =1-EXP(-(A_M+B_M*gm_c^$A19*(gm_c-1)/LN(gm_c))) -> 0.00043374231 | C19: =1-EXP(-(A_F+B_F*gm_c^$A19*(gm_c-1)/LN(gm_c))) -> 0.00030126052
A20: 28 | B20: =1-EXP(-(A_M+B_M*gm_c^$A20*(gm_c-1)/LN(gm_c))) -> 0.00045711554 | C20: =1-EXP(-(A_F+B_F*gm_c^$A20*(gm_c-1)/LN(gm_c))) -> 0.00031638644
A21: 29 | B21: =1-EXP(-(A_M+B_M*gm_c^$A21*(gm_c-1)/LN(gm_c))) -> 0.00048282546 | C21: =1-EXP(-(A_F+B_F*gm_c^$A21*(gm_c-1)/LN(gm_c))) -> 0.00033302469
... A112: 120 | B112: =1-EXP(-(A_M+B_M*gm_c^$A112*(gm_c-1)/LN(gm_c))) -> 0.80867951 | C112: =1-EXP(-(A_F+B_F*gm_c^$A112*(gm_c-1)/LN(gm_c))) -> 0.65703603

Sheet P01
A1: Inputs (section 3.1, from section 13) and the run-level valuation_date (3.3), typed
A2: valuation_date | B2: 46388 | C2: 3.3 | D2: Date, first of a month (run-level input)
A3: policy_id | B3: P01 | C3: 3.1 | D3: string
A4: sex | B4: M | C4: 3.1 | D4: string, M or F
A5: birth_date | B5: 31486 | C5: 3.1 | D5: Date
A6: entry_date | B6: 45474 | C6: 3.1 | D6: Date
A7: maturity_date | B7: 52779 | C7: 3.1 | D7: Date
A8: prem_term_y | B8: 20 | C8: 3.1 | D8: Int (years)
A9: sum_assured | B9: 250000 | C9: 3.1 | D9: Money per policy
A10: premium | B10: 52.96 | C10: 3.1 | D10: Money per policy, monthly, in advance
A11: pols_if_init | B11: 1 | C11: 3.1 | D11: Count
A13: Derived constants (sections 3.2, 4.3 and 5), by formula
A14: age_at_entry | B14: =YEAR(entry_date)-YEAR(birth_date)-IF(OR(MONTH(entry_date)<MONTH(birth_date),AND(MONTH(entry_date)=MONTH(birth_date),DAY(entry_date)<DAY(birth_date))),1,0) -> 38 | C14: 5 | D14: Int (years)
A15: dur_m | B15: =12*(YEAR(valuation_date)-YEAR(entry_date))+(MONTH(valuation_date)-MONTH(entry_date))-IF(DAY(valuation_date)<DAY(entry_date),1,0) -> 30 | C15: 4.3 | D15: Int (months)
A16: term_m | B16: =12*(YEAR(maturity_date)-YEAR(entry_date))+(MONTH(maturity_date)-MONTH(entry_date))-IF(DAY(maturity_date)<DAY(entry_date),1,0) -> 240 | C16: 4.3 | D16: Int (months)
A17: rem_m | B17: =term_m-dur_m -> 210 | C17: 4.3 | D17: Int (months)
A18: prem_term_m | B18: =12*prem_term_y -> 240 | C18: 4.3 | D18: Int (months)
A19: prem_rem_m | B19: =MAX(prem_term_m-dur_m,0) -> 210 | C19: 4.3 | D19: Int (months)
A20: dur_y_last | B20: =INT((term_m-1)/12) -> 19 | C20: 4.3 | D20: Int (years)
A22: Basis constants (section 6), each in one cell
A23: i | B23: 0.04 | C23: 6 | D23: Rate[Annual]
A24: e | B24: 0.03 | C24: 6 | D24: Rate[Annual]
A25: i_m | B25: =(1+i)^(1/12)-1 -> 0.0032737398 | C25: 6 | D25: Rate[Monthly]
A26: v_m | B26: =(1+i)^(-1/12) -> 0.99673694 | C26: 6 | D26: factor
A27: e_m | B27: =(1+e)^(1/12)-1 -> 0.0024662698 | C27: 6 | D27: Rate[Monthly]
A28: A_M | B28: 0.0002 | C28: 6.1 | D28: Gompertz-Makeham A, sex M
A29: A_F | B29: 0.00015 | C29: 6.1 | D29: Gompertz-Makeham A, sex F
A30: B_M | B30: 1.7e-05 | C30: 6.1 | D30: Gompertz-Makeham B, sex M
A31: B_F | B31: 1.1e-05 | C31: 6.1 | D31: Gompertz-Makeham B, sex F
A32: c | B32: 1.1 | C32: 6.1 | D32: Gompertz-Makeham c (both sexes); defined name gm_c
A33: maint_base | B33: 5 | C33: 6.5 | D33: Money per policy, per month, time-0 prices
A34: claim_exp_base | B34: 250 | C34: 6.5 | D34: Money per policy (per death), time-0 prices
A36: Lapse table (section 6.2): key k = min(dur_y, 5)
A37: k | B37: lapse_table | D37: Prob, annual
A38: 0 | B38: 0.15
A39: 1 | B39: 0.1
A40: 2 | B40: 0.08
A41: 3 | B41: 0.06
A42: 4 | B42: 0.05
A43: 5 | B43: 0.04
...

Sheet P02
A1: Inputs (section 3.1, from section 13) and the run-level valuation_date (3.3), typed
A2: valuation_date | B2: 46388 | C2: 3.3 | D2: Date, first of a month (run-level input)
A3: policy_id | B3: P02 | C3: 3.1 | D3: string
A4: sex | B4: F | C4: 3.1 | D4: string, M or F
A5: birth_date | B5: 33544 | C5: 3.1 | D5: Date
A6: entry_date | B6: 46388 | C6: 3.1 | D6: Date
A7: maturity_date | B7: 55519 | C7: 3.1 | D7: Date
A8: prem_term_y | B8: 25 | C8: 3.1 | D8: Int (years)
A9: sum_assured | B9: 400000 | C9: 3.1 | D9: Money per policy
A10: premium | B10: 51.64 | C10: 3.1 | D10: Money per policy, monthly, in advance
A11: pols_if_init | B11: 1 | C11: 3.1 | D11: Count
A13: Derived constants (sections 3.2, 4.3 and 5), by formula
A14: age_at_entry | B14: =YEAR(entry_date)-YEAR(birth_date)-IF(OR(MONTH(entry_date)<MONTH(birth_date),AND(MONTH(entry_date)=MONTH(birth_date),DAY(entry_date)<DAY(birth_date))),1,0) -> 35 | C14: 5 | D14: Int (years)
A15: dur_m | B15: =12*(YEAR(valuation_date)-YEAR(entry_date))+(MONTH(valuation_date)-MONTH(entry_date))-IF(DAY(valuation_date)<DAY(entry_date),1,0) -> 0 | C15: 4.3 | D15: Int (months)
A16: term_m | B16: =12*(YEAR(maturity_date)-YEAR(entry_date))+(MONTH(maturity_date)-MONTH(entry_date))-IF(DAY(maturity_date)<DAY(entry_date),1,0) -> 300 | C16: 4.3 | D16: Int (months)
A17: rem_m | B17: =term_m-dur_m -> 300 | C17: 4.3 | D17: Int (months)
A18: prem_term_m | B18: =12*prem_term_y -> 300 | C18: 4.3 | D18: Int (months)
A19: prem_rem_m | B19: =MAX(prem_term_m-dur_m,0) -> 300 | C19: 4.3 | D19: Int (months)
A20: dur_y_last | B20: =INT((term_m-1)/12) -> 24 | C20: 4.3 | D20: Int (years)
A22: Basis constants (section 6), each in one cell
A23: i | B23: 0.04 | C23: 6 | D23: Rate[Annual]
A24: e | B24: 0.03 | C24: 6 | D24: Rate[Annual]
A25: i_m | B25: =(1+i)^(1/12)-1 -> 0.0032737398 | C25: 6 | D25: Rate[Monthly]
A26: v_m | B26: =(1+i)^(-1/12) -> 0.99673694 | C26: 6 | D26: factor
A27: e_m | B27: =(1+e)^(1/12)-1 -> 0.0024662698 | C27: 6 | D27: Rate[Monthly]
A28: A_M | B28: 0.0002 | C28: 6.1 | D28: Gompertz-Makeham A, sex M
A29: A_F | B29: 0.00015 | C29: 6.1 | D29: Gompertz-Makeham A, sex F
A30: B_M | B30: 1.7e-05 | C30: 6.1 | D30: Gompertz-Makeham B, sex M
A31: B_F | B31: 1.1e-05 | C31: 6.1 | D31: Gompertz-Makeham B, sex F
A32: c | B32: 1.1 | C32: 6.1 | D32: Gompertz-Makeham c (both sexes); defined name gm_c
A33: maint_base | B33: 5 | C33: 6.5 | D33: Money per policy, per month, time-0 prices
A34: claim_exp_base | B34: 250 | C34: 6.5 | D34: Money per policy (per death), time-0 prices
A36: Lapse table (section 6.2): key k = min(dur_y, 5)
A37: k | B37: lapse_table | D37: Prob, annual
A38: 0 | B38: 0.15
A39: 1 | B39: 0.1
A40: 2 | B40: 0.08
A41: 3 | B41: 0.06
A42: 4 | B42: 0.05
A43: 5 | B43: 0.04
...

Sheet P03
A1: Inputs (section 3.1, from section 13) and the run-level valuation_date (3.3), typed
A2: valuation_date | B2: 46388 | C2: 3.3 | D2: Date, first of a month (run-level input)
A3: policy_id | B3: P03 | C3: 3.1 | D3: string
A4: sex | B4: M | C4: 3.1 | D4: string, M or F
A5: birth_date | B5: 24247 | C5: 3.1 | D5: Date
A6: entry_date | B6: 39097 | C6: 3.1 | D6: Date
A7: maturity_date | B7: 46402 | C7: 3.1 | D7: Date
A8: prem_term_y | B8: 20 | C8: 3.1 | D8: Int (years)
A9: sum_assured | B9: 150000 | C9: 3.1 | D9: Money per policy
A10: premium | B10: 39.99 | C10: 3.1 | D10: Money per policy, monthly, in advance
A11: pols_if_init | B11: 1 | C11: 3.1 | D11: Count
A13: Derived constants (sections 3.2, 4.3 and 5), by formula
A14: age_at_entry | B14: =YEAR(entry_date)-YEAR(birth_date)-IF(OR(MONTH(entry_date)<MONTH(birth_date),AND(MONTH(entry_date)=MONTH(birth_date),DAY(entry_date)<DAY(birth_date))),1,0) -> 40 | C14: 5 | D14: Int (years)
A15: dur_m | B15: =12*(YEAR(valuation_date)-YEAR(entry_date))+(MONTH(valuation_date)-MONTH(entry_date))-IF(DAY(valuation_date)<DAY(entry_date),1,0) -> 239 | C15: 4.3 | D15: Int (months)
A16: term_m | B16: =12*(YEAR(maturity_date)-YEAR(entry_date))+(MONTH(maturity_date)-MONTH(entry_date))-IF(DAY(maturity_date)<DAY(entry_date),1,0) -> 240 | C16: 4.3 | D16: Int (months)
A17: rem_m | B17: =term_m-dur_m -> 1 | C17: 4.3 | D17: Int (months)
A18: prem_term_m | B18: =12*prem_term_y -> 240 | C18: 4.3 | D18: Int (months)
A19: prem_rem_m | B19: =MAX(prem_term_m-dur_m,0) -> 1 | C19: 4.3 | D19: Int (months)
A20: dur_y_last | B20: =INT((term_m-1)/12) -> 19 | C20: 4.3 | D20: Int (years)
A22: Basis constants (section 6), each in one cell
A23: i | B23: 0.04 | C23: 6 | D23: Rate[Annual]
A24: e | B24: 0.03 | C24: 6 | D24: Rate[Annual]
A25: i_m | B25: =(1+i)^(1/12)-1 -> 0.0032737398 | C25: 6 | D25: Rate[Monthly]
A26: v_m | B26: =(1+i)^(-1/12) -> 0.99673694 | C26: 6 | D26: factor
A27: e_m | B27: =(1+e)^(1/12)-1 -> 0.0024662698 | C27: 6 | D27: Rate[Monthly]
A28: A_M | B28: 0.0002 | C28: 6.1 | D28: Gompertz-Makeham A, sex M
A29: A_F | B29: 0.00015 | C29: 6.1 | D29: Gompertz-Makeham A, sex F
A30: B_M | B30: 1.7e-05 | C30: 6.1 | D30: Gompertz-Makeham B, sex M
A31: B_F | B31: 1.1e-05 | C31: 6.1 | D31: Gompertz-Makeham B, sex F
A32: c | B32: 1.1 | C32: 6.1 | D32: Gompertz-Makeham c (both sexes); defined name gm_c
A33: maint_base | B33: 5 | C33: 6.5 | D33: Money per policy, per month, time-0 prices
A34: claim_exp_base | B34: 250 | C34: 6.5 | D34: Money per policy (per death), time-0 prices
A36: Lapse table (section 6.2): key k = min(dur_y, 5)
A37: k | B37: lapse_table | D37: Prob, annual
A38: 0 | B38: 0.15
A39: 1 | B39: 0.1
A40: 2 | B40: 0.08
A41: 3 | B41: 0.06
A42: 4 | B42: 0.05
A43: 5 | B43: 0.04
...

Sheet P04
A1: Inputs (section 3.1, from section 13) and the run-level valuation_date (3.3), typed
A2: valuation_date | B2: 46388 | C2: 3.3 | D2: Date, first of a month (run-level input)
A3: policy_id | B3: P04 | C3: 3.1 | D3: string
A4: sex | B4: F | C4: 3.1 | D4: string, M or F
A5: birth_date | B5: 27981 | C5: 3.1 | D5: Date
A6: entry_date | B6: 42083 | C6: 3.1 | D6: Date
A7: maturity_date | B7: 53041 | C7: 3.1 | D7: Date
A8: prem_term_y | B8: 20 | C8: 3.1 | D8: Int (years)
A9: sum_assured | B9: 300000 | C9: 3.1 | D9: Money per policy
A10: premium | B10: 68.98 | C10: 3.1 | D10: Money per policy, monthly, in advance
A11: pols_if_init | B11: 1 | C11: 3.1 | D11: Count
A13: Derived constants (sections 3.2, 4.3 and 5), by formula
A14: age_at_entry | B14: =YEAR(entry_date)-YEAR(birth_date)-IF(OR(MONTH(entry_date)<MONTH(birth_date),AND(MONTH(entry_date)=MONTH(birth_date),DAY(entry_date)<DAY(birth_date))),1,0) -> 38 | C14: 5 | D14: Int (years)
A15: dur_m | B15: =12*(YEAR(valuation_date)-YEAR(entry_date))+(MONTH(valuation_date)-MONTH(entry_date))-IF(DAY(valuation_date)<DAY(entry_date),1,0) -> 141 | C15: 4.3 | D15: Int (months)
A16: term_m | B16: =12*(YEAR(maturity_date)-YEAR(entry_date))+(MONTH(maturity_date)-MONTH(entry_date))-IF(DAY(maturity_date)<DAY(entry_date),1,0) -> 360 | C16: 4.3 | D16: Int (months)
A17: rem_m | B17: =term_m-dur_m -> 219 | C17: 4.3 | D17: Int (months)
A18: prem_term_m | B18: =12*prem_term_y -> 240 | C18: 4.3 | D18: Int (months)
A19: prem_rem_m | B19: =MAX(prem_term_m-dur_m,0) -> 99 | C19: 4.3 | D19: Int (months)
A20: dur_y_last | B20: =INT((term_m-1)/12) -> 29 | C20: 4.3 | D20: Int (years)
A22: Basis constants (section 6), each in one cell
A23: i | B23: 0.04 | C23: 6 | D23: Rate[Annual]
A24: e | B24: 0.03 | C24: 6 | D24: Rate[Annual]
A25: i_m | B25: =(1+i)^(1/12)-1 -> 0.0032737398 | C25: 6 | D25: Rate[Monthly]
A26: v_m | B26: =(1+i)^(-1/12) -> 0.99673694 | C26: 6 | D26: factor
A27: e_m | B27: =(1+e)^(1/12)-1 -> 0.0024662698 | C27: 6 | D27: Rate[Monthly]
A28: A_M | B28: 0.0002 | C28: 6.1 | D28: Gompertz-Makeham A, sex M
A29: A_F | B29: 0.00015 | C29: 6.1 | D29: Gompertz-Makeham A, sex F
A30: B_M | B30: 1.7e-05 | C30: 6.1 | D30: Gompertz-Makeham B, sex M
A31: B_F | B31: 1.1e-05 | C31: 6.1 | D31: Gompertz-Makeham B, sex F
A32: c | B32: 1.1 | C32: 6.1 | D32: Gompertz-Makeham c (both sexes); defined name gm_c
A33: maint_base | B33: 5 | C33: 6.5 | D33: Money per policy, per month, time-0 prices
A34: claim_exp_base | B34: 250 | C34: 6.5 | D34: Money per policy (per death), time-0 prices
A36: Lapse table (section 6.2): key k = min(dur_y, 5)
A37: k | B37: lapse_table | D37: Prob, annual
A38: 0 | B38: 0.15
A39: 1 | B39: 0.1
A40: 2 | B40: 0.08
A41: 3 | B41: 0.06
A42: 4 | B42: 0.05
A43: 5 | B43: 0.04
...

Sheet P05
A1: Inputs (section 3.1, from section 13) and the run-level valuation_date (3.3), typed
A2: valuation_date | B2: 46388 | C2: 3.3 | D2: Date, first of a month (run-level input)
A3: policy_id | B3: P05 | C3: 3.1 | D3: string
A4: sex | B4: M | C4: 3.1 | D4: string, M or F
A5: birth_date | B5: 27502 | C5: 3.1 | D5: Date
A6: entry_date | B6: 43141 | C6: 3.1 | D6: Date
A7: maturity_date | B7: 46793 | C7: 3.1 | D7: Date
A8: prem_term_y | B8: 9 | C8: 3.1 | D8: Int (years)
A9: sum_assured | B9: 200000 | C9: 3.1 | D9: Money per policy
A10: premium | B10: 46.4 | C10: 3.1 | D10: Money per policy, monthly, in advance
A11: pols_if_init | B11: 1 | C11: 3.1 | D11: Count
A13: Derived constants (sections 3.2, 4.3 and 5), by formula
A14: age_at_entry | B14: =YEAR(entry_date)-YEAR(birth_date)-IF(OR(MONTH(entry_date)<MONTH(birth_date),AND(MONTH(entry_date)=MONTH(birth_date),DAY(entry_date)<DAY(birth_date))),1,0) -> 42 | C14: 5 | D14: Int (years)
A15: dur_m | B15: =12*(YEAR(valuation_date)-YEAR(entry_date))+(MONTH(valuation_date)-MONTH(entry_date))-IF(DAY(valuation_date)<DAY(entry_date),1,0) -> 106 | C15: 4.3 | D15: Int (months)
A16: term_m | B16: =12*(YEAR(maturity_date)-YEAR(entry_date))+(MONTH(maturity_date)-MONTH(entry_date))-IF(DAY(maturity_date)<DAY(entry_date),1,0) -> 120 | C16: 4.3 | D16: Int (months)
A17: rem_m | B17: =term_m-dur_m -> 14 | C17: 4.3 | D17: Int (months)
A18: prem_term_m | B18: =12*prem_term_y -> 108 | C18: 4.3 | D18: Int (months)
A19: prem_rem_m | B19: =MAX(prem_term_m-dur_m,0) -> 2 | C19: 4.3 | D19: Int (months)
A20: dur_y_last | B20: =INT((term_m-1)/12) -> 9 | C20: 4.3 | D20: Int (years)
A22: Basis constants (section 6), each in one cell
A23: i | B23: 0.04 | C23: 6 | D23: Rate[Annual]
A24: e | B24: 0.03 | C24: 6 | D24: Rate[Annual]
A25: i_m | B25: =(1+i)^(1/12)-1 -> 0.0032737398 | C25: 6 | D25: Rate[Monthly]
A26: v_m | B26: =(1+i)^(-1/12) -> 0.99673694 | C26: 6 | D26: factor
A27: e_m | B27: =(1+e)^(1/12)-1 -> 0.0024662698 | C27: 6 | D27: Rate[Monthly]
A28: A_M | B28: 0.0002 | C28: 6.1 | D28: Gompertz-Makeham A, sex M
A29: A_F | B29: 0.00015 | C29: 6.1 | D29: Gompertz-Makeham A, sex F
A30: B_M | B30: 1.7e-05 | C30: 6.1 | D30: Gompertz-Makeham B, sex M
A31: B_F | B31: 1.1e-05 | C31: 6.1 | D31: Gompertz-Makeham B, sex F
A32: c | B32: 1.1 | C32: 6.1 | D32: Gompertz-Makeham c (both sexes); defined name gm_c
A33: maint_base | B33: 5 | C33: 6.5 | D33: Money per policy, per month, time-0 prices
A34: claim_exp_base | B34: 250 | C34: 6.5 | D34: Money per policy (per death), time-0 prices
A36: Lapse table (section 6.2): key k = min(dur_y, 5)
A37: k | B37: lapse_table | D37: Prob, annual
A38: 0 | B38: 0.15
A39: 1 | B39: 0.1
A40: 2 | B40: 0.08
A41: 3 | B41: 0.06
A42: 4 | B42: 0.05
A43: 5 | B43: 0.04
...

Sheet P06
A1: Inputs (section 3.1, from section 13) and the run-level valuation_date (3.3), typed
A2: valuation_date | B2: 46388 | C2: 3.3 | D2: Date, first of a month (run-level input)
A3: policy_id | B3: P06 | C3: 3.1 | D3: string
A4: sex | B4: F | C4: 3.1 | D4: string, M or F
A5: birth_date | B5: 37680 | C5: 3.1 | D5: Date
A6: entry_date | B6: 46336 | C6: 3.1 | D6: Date
A7: maturity_date | B7: 49989 | C7: 3.1 | D7: Date
A8: prem_term_y | B8: 10 | C8: 3.1 | D8: Int (years)
A9: sum_assured | B9: 100000 | C9: 3.1 | D9: Money per policy
A10: premium | B10: 10.76 | C10: 3.1 | D10: Money per policy, monthly, in advance
A11: pols_if_init | B11: 1 | C11: 3.1 | D11: Count
A13: Derived constants (sections 3.2, 4.3 and 5), by formula
A14: age_at_entry | B14: =YEAR(entry_date)-YEAR(birth_date)-IF(OR(MONTH(entry_date)<MONTH(birth_date),AND(MONTH(entry_date)=MONTH(birth_date),DAY(entry_date)<DAY(birth_date))),1,0) -> 23 | C14: 5 | D14: Int (years)
A15: dur_m | B15: =12*(YEAR(valuation_date)-YEAR(entry_date))+(MONTH(valuation_date)-MONTH(entry_date))-IF(DAY(valuation_date)<DAY(entry_date),1,0) -> 1 | C15: 4.3 | D15: Int (months)
A16: term_m | B16: =12*(YEAR(maturity_date)-YEAR(entry_date))+(MONTH(maturity_date)-MONTH(entry_date))-IF(DAY(maturity_date)<DAY(entry_date),1,0) -> 120 | C16: 4.3 | D16: Int (months)
A17: rem_m | B17: =term_m-dur_m -> 119 | C17: 4.3 | D17: Int (months)
A18: prem_term_m | B18: =12*prem_term_y -> 120 | C18: 4.3 | D18: Int (months)
A19: prem_rem_m | B19: =MAX(prem_term_m-dur_m,0) -> 119 | C19: 4.3 | D19: Int (months)
A20: dur_y_last | B20: =INT((term_m-1)/12) -> 9 | C20: 4.3 | D20: Int (years)
A22: Basis constants (section 6), each in one cell
A23: i | B23: 0.04 | C23: 6 | D23: Rate[Annual]
A24: e | B24: 0.03 | C24: 6 | D24: Rate[Annual]
A25: i_m | B25: =(1+i)^(1/12)-1 -> 0.0032737398 | C25: 6 | D25: Rate[Monthly]
A26: v_m | B26: =(1+i)^(-1/12) -> 0.99673694 | C26: 6 | D26: factor
A27: e_m | B27: =(1+e)^(1/12)-1 -> 0.0024662698 | C27: 6 | D27: Rate[Monthly]
A28: A_M | B28: 0.0002 | C28: 6.1 | D28: Gompertz-Makeham A, sex M
A29: A_F | B29: 0.00015 | C29: 6.1 | D29: Gompertz-Makeham A, sex F
A30: B_M | B30: 1.7e-05 | C30: 6.1 | D30: Gompertz-Makeham B, sex M
A31: B_F | B31: 1.1e-05 | C31: 6.1 | D31: Gompertz-Makeham B, sex F
A32: c | B32: 1.1 | C32: 6.1 | D32: Gompertz-Makeham c (both sexes); defined name gm_c
A33: maint_base | B33: 5 | C33: 6.5 | D33: Money per policy, per month, time-0 prices
A34: claim_exp_base | B34: 250 | C34: 6.5 | D34: Money per policy (per death), time-0 prices
A36: Lapse table (section 6.2): key k = min(dur_y, 5)
A37: k | B37: lapse_table | D37: Prob, annual
A38: 0 | B38: 0.15
A39: 1 | B39: 0.1
A40: 2 | B40: 0.08
A41: 3 | B41: 0.06
A42: 4 | B42: 0.05
A43: 5 | B43: 0.04
...

Sheet P07
A1: Inputs (section 3.1, from section 13) and the run-level valuation_date (3.3), typed
A2: valuation_date | B2: 46388 | C2: 3.3 | D2: Date, first of a month (run-level input)
A3: policy_id | B3: P07 | C3: 3.1 | D3: string
A4: sex | B4: M | C4: 3.1 | D4: string, M or F
A5: birth_date | B5: 29373 | C5: 3.1 | D5: Date
A6: entry_date | B6: 43890 | C6: 3.1 | D6: Date
A7: maturity_date | B7: 51195 | C7: 3.1 | D7: Date
A8: prem_term_y | B8: 20 | C8: 3.1 | D8: Int (years)
A9: sum_assured | B9: 500000 | C9: 3.1 | D9: Money per policy
A10: premium | B10: 105.55 | C10: 3.1 | D10: Money per policy, monthly, in advance
A11: pols_if_init | B11: 2.5 | C11: 3.1 | D11: Count
A13: Derived constants (sections 3.2, 4.3 and 5), by formula
A14: age_at_entry | B14: =YEAR(entry_date)-YEAR(birth_date)-IF(OR(MONTH(entry_date)<MONTH(birth_date),AND(MONTH(entry_date)=MONTH(birth_date),DAY(entry_date)<DAY(birth_date))),1,0) -> 39 | C14: 5 | D14: Int (years)
A15: dur_m | B15: =12*(YEAR(valuation_date)-YEAR(entry_date))+(MONTH(valuation_date)-MONTH(entry_date))-IF(DAY(valuation_date)<DAY(entry_date),1,0) -> 82 | C15: 4.3 | D15: Int (months)
A16: term_m | B16: =12*(YEAR(maturity_date)-YEAR(entry_date))+(MONTH(maturity_date)-MONTH(entry_date))-IF(DAY(maturity_date)<DAY(entry_date),1,0) -> 240 | C16: 4.3 | D16: Int (months)
A17: rem_m | B17: =term_m-dur_m -> 158 | C17: 4.3 | D17: Int (months)
A18: prem_term_m | B18: =12*prem_term_y -> 240 | C18: 4.3 | D18: Int (months)
A19: prem_rem_m | B19: =MAX(prem_term_m-dur_m,0) -> 158 | C19: 4.3 | D19: Int (months)
A20: dur_y_last | B20: =INT((term_m-1)/12) -> 19 | C20: 4.3 | D20: Int (years)
A22: Basis constants (section 6), each in one cell
A23: i | B23: 0.04 | C23: 6 | D23: Rate[Annual]
A24: e | B24: 0.03 | C24: 6 | D24: Rate[Annual]
A25: i_m | B25: =(1+i)^(1/12)-1 -> 0.0032737398 | C25: 6 | D25: Rate[Monthly]
A26: v_m | B26: =(1+i)^(-1/12) -> 0.99673694 | C26: 6 | D26: factor
A27: e_m | B27: =(1+e)^(1/12)-1 -> 0.0024662698 | C27: 6 | D27: Rate[Monthly]
A28: A_M | B28: 0.0002 | C28: 6.1 | D28: Gompertz-Makeham A, sex M
A29: A_F | B29: 0.00015 | C29: 6.1 | D29: Gompertz-Makeham A, sex F
A30: B_M | B30: 1.7e-05 | C30: 6.1 | D30: Gompertz-Makeham B, sex M
A31: B_F | B31: 1.1e-05 | C31: 6.1 | D31: Gompertz-Makeham B, sex F
A32: c | B32: 1.1 | C32: 6.1 | D32: Gompertz-Makeham c (both sexes); defined name gm_c
A33: maint_base | B33: 5 | C33: 6.5 | D33: Money per policy, per month, time-0 prices
A34: claim_exp_base | B34: 250 | C34: 6.5 | D34: Money per policy (per death), time-0 prices
A36: Lapse table (section 6.2): key k = min(dur_y, 5)
A37: k | B37: lapse_table | D37: Prob, annual
A38: 0 | B38: 0.15
A39: 1 | B39: 0.1
A40: 2 | B40: 0.08
A41: 3 | B41: 0.06
A42: 4 | B42: 0.05
A43: 5 | B43: 0.04
...

Sheet P08
A1: Inputs (section 3.1, from section 13) and the run-level valuation_date (3.3), typed
A2: valuation_date | B2: 46388 | C2: 3.3 | D2: Date, first of a month (run-level input)
A3: policy_id | B3: P08 | C3: 3.1 | D3: string
A4: sex | B4: M | C4: 3.1 | D4: string, M or F
A5: birth_date | B5: 21550 | C5: 3.1 | D5: Date
A6: entry_date | B6: 40543 | C6: 3.1 | D6: Date
A7: maturity_date | B7: 47848 | C7: 3.1 | D7: Date
A8: prem_term_y | B8: 10 | C8: 3.1 | D8: Int (years)
A9: sum_assured | B9: 120000 | C9: 3.1 | D9: Money per policy
A10: premium | B10: 128.12 | C10: 3.1 | D10: Money per policy, monthly, in advance
A11: pols_if_init | B11: 1 | C11: 3.1 | D11: Count
A13: Derived constants (sections 3.2, 4.3 and 5), by formula
A14: age_at_entry | B14: =YEAR(entry_date)-YEAR(birth_date)-IF(OR(MONTH(entry_date)<MONTH(birth_date),AND(MONTH(entry_date)=MONTH(birth_date),DAY(entry_date)<DAY(birth_date))),1,0) -> 52 | C14: 5 | D14: Int (years)
A15: dur_m | B15: =12*(YEAR(valuation_date)-YEAR(entry_date))+(MONTH(valuation_date)-MONTH(entry_date))-IF(DAY(valuation_date)<DAY(entry_date),1,0) -> 192 | C15: 4.3 | D15: Int (months)
A16: term_m | B16: =12*(YEAR(maturity_date)-YEAR(entry_date))+(MONTH(maturity_date)-MONTH(entry_date))-IF(DAY(maturity_date)<DAY(entry_date),1,0) -> 240 | C16: 4.3 | D16: Int (months)
A17: rem_m | B17: =term_m-dur_m -> 48 | C17: 4.3 | D17: Int (months)
A18: prem_term_m | B18: =12*prem_term_y -> 120 | C18: 4.3 | D18: Int (months)
A19: prem_rem_m | B19: =MAX(prem_term_m-dur_m,0) -> 0 | C19: 4.3 | D19: Int (months)
A20: dur_y_last | B20: =INT((term_m-1)/12) -> 19 | C20: 4.3 | D20: Int (years)
A22: Basis constants (section 6), each in one cell
A23: i | B23: 0.04 | C23: 6 | D23: Rate[Annual]
A24: e | B24: 0.03 | C24: 6 | D24: Rate[Annual]
A25: i_m | B25: =(1+i)^(1/12)-1 -> 0.0032737398 | C25: 6 | D25: Rate[Monthly]
A26: v_m | B26: =(1+i)^(-1/12) -> 0.99673694 | C26: 6 | D26: factor
A27: e_m | B27: =(1+e)^(1/12)-1 -> 0.0024662698 | C27: 6 | D27: Rate[Monthly]
A28: A_M | B28: 0.0002 | C28: 6.1 | D28: Gompertz-Makeham A, sex M
A29: A_F | B29: 0.00015 | C29: 6.1 | D29: Gompertz-Makeham A, sex F
A30: B_M | B30: 1.7e-05 | C30: 6.1 | D30: Gompertz-Makeham B, sex M
A31: B_F | B31: 1.1e-05 | C31: 6.1 | D31: Gompertz-Makeham B, sex F
A32: c | B32: 1.1 | C32: 6.1 | D32: Gompertz-Makeham c (both sexes); defined name gm_c
A33: maint_base | B33: 5 | C33: 6.5 | D33: Money per policy, per month, time-0 prices
A34: claim_exp_base | B34: 250 | C34: 6.5 | D34: Money per policy (per death), time-0 prices
A36: Lapse table (section 6.2): key k = min(dur_y, 5)
A37: k | B37: lapse_table | D37: Prob, annual
A38: 0 | B38: 0.15
A39: 1 | B39: 0.1
A40: 2 | B40: 0.08
A41: 3 | B41: 0.06
A42: 4 | B42: 0.05
A43: 5 | B43: 0.04
...

Sheet P09
A1: Inputs (section 3.1, from section 13) and the run-level valuation_date (3.3), typed
A2: valuation_date | B2: 46388 | C2: 3.3 | D2: Date, first of a month (run-level input)
A3: policy_id | B3: P09 | C3: 3.1 | D3: string
A4: sex | B4: F | C4: 3.1 | D4: string, M or F
A5: birth_date | B5: 35369 | C5: 3.1 | D5: Date
A6: entry_date | B6: 46371 | C6: 3.1 | D6: Date
A7: maturity_date | B7: 60981 | C7: 3.1 | D7: Date
A8: prem_term_y | B8: 40 | C8: 3.1 | D8: Int (years)
A9: sum_assured | B9: 1000000 | C9: 3.1 | D9: Money per policy
A10: premium | B10: 116.62 | C10: 3.1 | D10: Money per policy, monthly, in advance
A11: pols_if_init | B11: 1 | C11: 3.1 | D11: Count
A13: Derived constants (sections 3.2, 4.3 and 5), by formula
A14: age_at_entry | B14: =YEAR(entry_date)-YEAR(birth_date)-IF(OR(MONTH(entry_date)<MONTH(birth_date),AND(MONTH(entry_date)=MONTH(birth_date),DAY(entry_date)<DAY(birth_date))),1,0) -> 30 | C14: 5 | D14: Int (years)
A15: dur_m | B15: =12*(YEAR(valuation_date)-YEAR(entry_date))+(MONTH(valuation_date)-MONTH(entry_date))-IF(DAY(valuation_date)<DAY(entry_date),1,0) -> 0 | C15: 4.3 | D15: Int (months)
A16: term_m | B16: =12*(YEAR(maturity_date)-YEAR(entry_date))+(MONTH(maturity_date)-MONTH(entry_date))-IF(DAY(maturity_date)<DAY(entry_date),1,0) -> 480 | C16: 4.3 | D16: Int (months)
A17: rem_m | B17: =term_m-dur_m -> 480 | C17: 4.3 | D17: Int (months)
A18: prem_term_m | B18: =12*prem_term_y -> 480 | C18: 4.3 | D18: Int (months)
A19: prem_rem_m | B19: =MAX(prem_term_m-dur_m,0) -> 480 | C19: 4.3 | D19: Int (months)
A20: dur_y_last | B20: =INT((term_m-1)/12) -> 39 | C20: 4.3 | D20: Int (years)
A22: Basis constants (section 6), each in one cell
A23: i | B23: 0.04 | C23: 6 | D23: Rate[Annual]
A24: e | B24: 0.03 | C24: 6 | D24: Rate[Annual]
A25: i_m | B25: =(1+i)^(1/12)-1 -> 0.0032737398 | C25: 6 | D25: Rate[Monthly]
A26: v_m | B26: =(1+i)^(-1/12) -> 0.99673694 | C26: 6 | D26: factor
A27: e_m | B27: =(1+e)^(1/12)-1 -> 0.0024662698 | C27: 6 | D27: Rate[Monthly]
A28: A_M | B28: 0.0002 | C28: 6.1 | D28: Gompertz-Makeham A, sex M
A29: A_F | B29: 0.00015 | C29: 6.1 | D29: Gompertz-Makeham A, sex F
A30: B_M | B30: 1.7e-05 | C30: 6.1 | D30: Gompertz-Makeham B, sex M
A31: B_F | B31: 1.1e-05 | C31: 6.1 | D31: Gompertz-Makeham B, sex F
A32: c | B32: 1.1 | C32: 6.1 | D32: Gompertz-Makeham c (both sexes); defined name gm_c
A33: maint_base | B33: 5 | C33: 6.5 | D33: Money per policy, per month, time-0 prices
A34: claim_exp_base | B34: 250 | C34: 6.5 | D34: Money per policy (per death), time-0 prices
A36: Lapse table (section 6.2): key k = min(dur_y, 5)
A37: k | B37: lapse_table | D37: Prob, annual
A38: 0 | B38: 0.15
A39: 1 | B39: 0.1
A40: 2 | B40: 0.08
A41: 3 | B41: 0.06
A42: 4 | B42: 0.05
A43: 5 | B43: 0.04
...

Sheet P10
A1: Inputs (section 3.1, from section 13) and the run-level valuation_date (3.3), typed
A2: valuation_date | B2: 46388 | C2: 3.3 | D2: Date, first of a month (run-level input)
A3: policy_id | B3: P10 | C3: 3.1 | D3: string
A4: sex | B4: M | C4: 3.1 | D4: string, M or F
A5: birth_date | B5: 32998 | C5: 3.1 | D5: Date
A6: entry_date | B6: 44593 | C6: 3.1 | D6: Date
A7: maturity_date | B7: 48245 | C7: 3.1 | D7: Date
A8: prem_term_y | B8: 5 | C8: 3.1 | D8: Int (years)
A9: sum_assured | B9: 200000 | C9: 3.1 | D9: Money per policy
A10: premium | B10: 39.27 | C10: 3.1 | D10: Money per policy, monthly, in advance
A11: pols_if_init | B11: 1 | C11: 3.1 | D11: Count
A13: Derived constants (sections 3.2, 4.3 and 5), by formula
A14: age_at_entry | B14: =YEAR(entry_date)-YEAR(birth_date)-IF(OR(MONTH(entry_date)<MONTH(birth_date),AND(MONTH(entry_date)=MONTH(birth_date),DAY(entry_date)<DAY(birth_date))),1,0) -> 31 | C14: 5 | D14: Int (years)
A15: dur_m | B15: =12*(YEAR(valuation_date)-YEAR(entry_date))+(MONTH(valuation_date)-MONTH(entry_date))-IF(DAY(valuation_date)<DAY(entry_date),1,0) -> 59 | C15: 4.3 | D15: Int (months)
A16: term_m | B16: =12*(YEAR(maturity_date)-YEAR(entry_date))+(MONTH(maturity_date)-MONTH(entry_date))-IF(DAY(maturity_date)<DAY(entry_date),1,0) -> 120 | C16: 4.3 | D16: Int (months)
A17: rem_m | B17: =term_m-dur_m -> 61 | C17: 4.3 | D17: Int (months)
A18: prem_term_m | B18: =12*prem_term_y -> 60 | C18: 4.3 | D18: Int (months)
A19: prem_rem_m | B19: =MAX(prem_term_m-dur_m,0) -> 1 | C19: 4.3 | D19: Int (months)
A20: dur_y_last | B20: =INT((term_m-1)/12) -> 9 | C20: 4.3 | D20: Int (years)
A22: Basis constants (section 6), each in one cell
A23: i | B23: 0.04 | C23: 6 | D23: Rate[Annual]
A24: e | B24: 0.03 | C24: 6 | D24: Rate[Annual]
A25: i_m | B25: =(1+i)^(1/12)-1 -> 0.0032737398 | C25: 6 | D25: Rate[Monthly]
A26: v_m | B26: =(1+i)^(-1/12) -> 0.99673694 | C26: 6 | D26: factor
A27: e_m | B27: =(1+e)^(1/12)-1 -> 0.0024662698 | C27: 6 | D27: Rate[Monthly]
A28: A_M | B28: 0.0002 | C28: 6.1 | D28: Gompertz-Makeham A, sex M
A29: A_F | B29: 0.00015 | C29: 6.1 | D29: Gompertz-Makeham A, sex F
A30: B_M | B30: 1.7e-05 | C30: 6.1 | D30: Gompertz-Makeham B, sex M
A31: B_F | B31: 1.1e-05 | C31: 6.1 | D31: Gompertz-Makeham B, sex F
A32: c | B32: 1.1 | C32: 6.1 | D32: Gompertz-Makeham c (both sexes); defined name gm_c
A33: maint_base | B33: 5 | C33: 6.5 | D33: Money per policy, per month, time-0 prices
A34: claim_exp_base | B34: 250 | C34: 6.5 | D34: Money per policy (per death), time-0 prices
A36: Lapse table (section 6.2): key k = min(dur_y, 5)
A37: k | B37: lapse_table | D37: Prob, annual
A38: 0 | B38: 0.15
A39: 1 | B39: 0.1
A40: 2 | B40: 0.08
A41: 3 | B41: 0.06
A42: 4 | B42: 0.05
A43: 5 | B43: 0.04
...

Sheet summary
A1: Scalars (section 11.2) per policy, by reference to the policy sheets; the row labelled total holds the section 11.3 scalar totals, plain SUMs in ascending policy_id order
A2: policy_id | B2: age_at_entry | C2: dur_m | D2: term_m | E2: rem_m | F2: prem_term_m | G2: prem_rem_m | H2: dur_y_last | I2: pv_premiums | J2: pv_commission | K2: pv_maint_expense | L2: pv_death_outgo | M2: pv_claim_expense | N2: pv_net_cf | O2: reserve_0 | P2: reserve_pp_0 | Q2: reserve_floored_0 | R2: maturities_n
A3: ='P01'!$B$3 -> P01 | B3: ='P01'!$B$265 -> 38 | C3: ='P01'!$B$266 -> 30 | D3: ='P01'!$B$267 -> 240 | E3: ='P01'!$B$268 -> 210 | F3: ='P01'!$B$269 -> 240 | G3: ='P01'!$B$270 -> 210 | H3: ='P01'!$B$271 -> 19 | I3: ='P01'!$B$272 -> 5662.0561 | J3: ='P01'!$B$273 -> 113.24112 | K3: ='P01'!$B$274 -> 656.93011 | L3: ='P01'!$B$275 -> 4232.3759 | M3: ='P01'!$B$276 -> 5.5602988 | N3: ='P01'!$B$277 -> 653.94869 | O3: ='P01'!$B$278 -> -653.94869 | P3: ='P01'!$B$279 -> -653.94869 | Q3: ='P01'!$B$280 -> 0 | R3: ='P01'!$B$281 -> 0.4461516
A4: ='P02'!$B$3 -> P02 | B4: ='P02'!$B$355 -> 35 | C4: ='P02'!$B$356 -> 0 | D4: ='P02'!$B$357 -> 300 | E4: ='P02'!$B$358 -> 300 | F4: ='P02'!$B$359 -> 300 | G4: ='P02'!$B$360 -> 300 | H4: ='P02'!$B$361 -> 24 | I4: ='P02'!$B$362 -> 5327.8947 | J4: ='P02'!$B$363 -> 208.39909 | K4: ='P02'!$B$364 -> 670.58943 | L4: ='P02'!$B$365 -> 3421.6369 | M4: ='P02'!$B$366 -> 3.1562144 | N4: ='P02'!$B$367 -> 1024.1131 | O4: ='P02'!$B$368 -> -1024.1131 | P4: ='P02'!$B$369 -> -1024.1131 | Q4: ='P02'!$B$370 -> 0 | R4: ='P02'!$B$371 -> 0.26806728
A5: ='P03'!$B$3 -> P03 | B5: ='P03'!$B$56 -> 40 | C5: ='P03'!$B$57 -> 239 | D5: ='P03'!$B$58 -> 240 | E5: ='P03'!$B$59 -> 1 | F5: ='P03'!$B$60 -> 240 | G5: ='P03'!$B$61 -> 1 | H5: ='P03'!$B$62 -> 19 | I5: ='P03'!$B$63 -> 39.99 | J5: ='P03'!$B$64 -> 0.7998 | K5: ='P03'!$B$65 -> 4.9959758 | L5: ='P03'!$B$66 -> 63.991387 | M5: ='P03'!$B$67 -> 0.10691535 | N5: ='P03'!$B$68 -> -29.904078 | O5: ='P03'!$B$69 -> 29.904078 | P5: ='P03'!$B$70 -> 29.904078 | Q5: ='P03'!$B$71 -> 29.904078 | R5: ='P03'!$B$72 -> 0.99617739
A6: ='P04'!$B$3 -> P04 | B6: ='P04'!$B$274 -> 38 | C6: ='P04'!$B$275 -> 141 | D6: ='P04'!$B$276 -> 360 | E6: ='P04'!$B$277 -> 219 | F6: ='P04'!$B$278 -> 240 | G6: ='P04'!$B$279 -> 99 | H6: ='P04'!$B$280 -> 29 | I6: ='P04'!$B$281 -> 4982.5837 | J6: ='P04'!$B$282 -> 99.651673 | K6: ='P04'!$B$283 -> 765.99821 | L6: ='P04'!$B$284 -> 9278.9681 | M6: ='P04'!$B$285 -> 10.531314 | N6: ='P04'!$B$286 -> -5172.5656 | O6: ='P04'!$B$287 -> 5172.5656 | P6: ='P04'!$B$288 -> 5172.5656 | Q6: ='P04'!$B$289 -> 5172.5656 | R6: ='P04'!$B$290 -> 0.6692441
A7: ='P05'!$B$3 -> P05 | B7: ='P05'!$B$69 -> 42 | C7: ='P05'!$B$70 -> 106 | D7: ='P05'!$B$71 -> 120 | E7: ='P05'!$B$72 -> 14 | F7: ='P05'!$B$73 -> 108 | G7: ='P05'!$B$74 -> 2 | H7: ='P05'!$B$75 -> 9 | I7: ='P05'!$B$76 -> 92.482722 | J7: ='P05'!$B$77 -> 1.8496544 | K7: ='P05'!$B$78 -> 69.066636 | L7: ='P05'!$B$79 -> 558.8157 | M7: ='P05'!$B$80 -> 0.71160094 | N7: ='P05'!$B$81 -> -537.96087 | O7: ='P05'!$B$82 -> 537.96087 | P7: ='P05'!$B$83 -> 537.96087 | Q7: ='P05'!$B$84 -> 537.96087 | R7: ='P05'!$B$85 -> 0.99035759
A8: ='P06'!$B$3 -> P06 | B8: ='P06'!$B$174 -> 23 | C8: ='P06'!$B$175 -> 1 | D8: ='P06'!$B$176 -> 120 | E8: ='P06'!$B$177 -> 119 | F8: ='P06'!$B$178 -> 120 | G8: ='P06'!$B$179 -> 119 | H8: ='P06'!$B$180 -> 9 | I8: ='P06'!$B$181 -> 726.6675 | J8: ='P06'!$B$182 -> 34.1462 | K8: ='P06'!$B$183 -> 382.24431 | L8: ='P06'!$B$184 -> 169.99815 | M8: ='P06'!$B$185 -> 0.48844375 | N8: ='P06'!$B$186 -> 139.7904 | O8: ='P06'!$B$187 -> -139.7904 | P8: ='P06'!$B$188 -> -139.7904 | Q8: ='P06'!$B$189 -> 0 | R8: ='P06'!$B$190 -> 0.51782268
A9: ='P07'!$B$3 -> P07 | B9: ='P07'!$B$213 -> 39 | C9: ='P07'!$B$214 -> 82 | D9: ='P07'!$B$215 -> 240 | E9: ='P07'!$B$216 -> 158 | F9: ='P07'!$B$217 -> 240 | G9: ='P07'!$B$218 -> 158 | H9: ='P07'!$B$219 -> 19 | I9: ='P07'!$B$220 -> 25545.752 | J9: ='P07'!$B$221 -> 510.91504 | K9: ='P07'!$B$222 -> 1425.6891 | L9: ='P07'!$B$223 -> 26085.518 | M9: ='P07'!$B$224 -> 15.997987 | N9: ='P07'!$B$225 -> -2492.3686 | O9: ='P07'!$B$226 -> 2492.3686 | P9: ='P07'!$B$227 -> 996.94743 | Q9: ='P07'!$B$228 -> 2492.3686 | R9: ='P07'!$B$229 -> 1.4061854
A10: ='P08'!$B$3 -> P08 | B10: ='P08'!$B$103 -> 52 | C10: ='P08'!$B$104 -> 192 | D10: ='P08'!$B$105 -> 240 | E10: ='P08'!$B$106 -> 48 | F10: ='P08'!$B$107 -> 120 | G10: ='P08'!$B$108 -> 0 | H10: ='P08'!$B$109 -> 19 | I10: ='P08'!$B$110 -> 0 | J10: ='P08'!$B$111 -> 0 | K10: ='P08'!$B$112 -> 229.53054 | L10: ='P08'!$B$113 -> 5892.7648 | M10: ='P08'!$B$114 -> 13.065936 | N10: ='P08'!$B$115 -> -6135.3613 | O10: ='P08'!$B$116 -> 6135.3613 | P10: ='P08'!$B$117 -> 6135.3613 | Q10: ='P08'!$B$118 -> 6135.3613 | R10: ='P08'!$B$119 -> 0.94664738
A11: ='P09'!$B$3 -> P09 | B11: ='P09'!$B$535 -> 30 | C11: ='P09'!$B$536 -> 0 | D11: ='P09'!$B$537 -> 480 | E11: ='P09'!$B$538 -> 480 | F11: ='P09'!$B$539 -> 480 | G11: ='P09'!$B$540 -> 480 | H11: ='P09'!$B$541 -> 39 | I11: ='P09'!$B$542 -> 13280.043 | J11: ='P09'!$B$543 -> 495.60407 | K11: ='P09'!$B$544 -> 803.96019 | L11: ='P09'!$B$545 -> 9419.3297 | M11: ='P09'!$B$546 -> 4.5107545 | N11: ='P09'!$B$547 -> 2556.6382 | O11: ='P09'!$B$548 -> -2556.6382 | P11: ='P09'!$B$549 -> -2556.6382 | Q11: ='P09'!$B$550 -> 0 | R11: ='P09'!$B$551 -> 0.13692356
A12: ='P10'!$B$3 -> P10 | B12: ='P10'!$B$116 -> 31 | C12: ='P10'!$B$117 -> 59 | D12: ='P10'!$B$118 -> 120 | E12: ='P10'!$B$119 -> 61 | F12: ='P10'!$B$120 -> 60 | G12: ='P10'!$B$121 -> 1 | H12: ='P10'!$B$122 -> 9 | I12: ='P10'!$B$123 -> 39.27 | J12: ='P10'!$B$124 -> 0.7854 | K12: ='P10'!$B$125 -> 295.66454 | L12: ='P10'!$B$126 -> 791.15893 | M12: ='P10'!$B$127 -> 1.0705245 | N12: ='P10'!$B$128 -> -1049.4094 | O12: ='P10'!$B$129 -> 1049.4094 | P12: ='P10'!$B$130 -> 1049.4094 | Q12: ='P10'!$B$131 -> 1049.4094 | R12: ='P10'!$B$132 -> 0.99133866
A13: total | I13: =SUM(I3:I12) -> 55696.74 | J13: =SUM(J3:J12) -> 1465.392 | K13: =SUM(K3:K12) -> 5304.669 | L13: =SUM(L3:L12) -> 59914.558 | M13: =SUM(M3:M12) -> 55.19999 | N13: =SUM(N3:N12) -> -11043.079 | O13: =SUM(O3:O12) -> 11043.079 | Q13: =SUM(Q3:Q12) -> 15417.57
A15: Check cells (section 12) per policy, by reference to the policy sheets: <id>_ok per (sheet) invariant, rows_ok, ok per policy, and all_ok over the ten policies
A16: policy_id | B16: H1_ok | C16: H2_ok | D16: H3_ok | E16: H4_ok | F16: H5a_ok | G16: H5b_ok | H16: P1_ok | I16: P2_ok | J16: P3_ok | K16: P4_ok | L16: P5_ok | M16: P6_ok | N16: P8_ok | O16: P9_ok | P16: P10_ok | Q16: rows_ok | R16: ok
A17: ='P01'!$B$3 -> P01 | B17: ='P01'!$B$290 -> TRUE | C17: ='P01'!$B$291 -> TRUE | D17: ='P01'!$B$292 -> TRUE | E17: ='P01'!$B$293 -> TRUE | F17: ='P01'!$B$294 -> TRUE | G17: ='P01'!$B$295 -> TRUE | H17: ='P01'!$B$296 -> TRUE | I17: ='P01'!$B$297 -> TRUE | J17: ='P01'!$B$298 -> TRUE | K17: ='P01'!$B$299 -> TRUE | L17: ='P01'!$B$300 -> TRUE | M17: ='P01'!$B$301 -> TRUE | N17: ='P01'!$B$302 -> TRUE | O17: ='P01'!$B$303 -> TRUE | P17: ='P01'!$B$304 -> TRUE | Q17: ='P01'!$B$305 -> TRUE | R17: ='P01'!$B$306 -> TRUE
A18: ='P02'!$B$3 -> P02 | B18: ='P02'!$B$380 -> TRUE | C18: ='P02'!$B$381 -> TRUE | D18: ='P02'!$B$382 -> TRUE | E18: ='P02'!$B$383 -> TRUE | F18: ='P02'!$B$384 -> TRUE | G18: ='P02'!$B$385 -> TRUE | H18: ='P02'!$B$386 -> TRUE | I18: ='P02'!$B$387 -> TRUE | J18: ='P02'!$B$388 -> TRUE | K18: ='P02'!$B$389 -> TRUE | L18: ='P02'!$B$390 -> TRUE | M18: ='P02'!$B$391 -> TRUE | N18: ='P02'!$B$392 -> TRUE | O18: ='P02'!$B$393 -> TRUE | P18: ='P02'!$B$394 -> TRUE | Q18: ='P02'!$B$395 -> TRUE | R18: ='P02'!$B$396 -> TRUE
A19: ='P03'!$B$3 -> P03 | B19: ='P03'!$B$81 -> TRUE | C19: ='P03'!$B$82 -> TRUE | D19: ='P03'!$B$83 -> TRUE | E19: ='P03'!$B$84 -> TRUE | F19: ='P03'!$B$85 -> TRUE | G19: ='P03'!$B$86 -> TRUE | H19: ='P03'!$B$87 -> TRUE | I19: ='P03'!$B$88 -> TRUE | J19: ='P03'!$B$89 -> TRUE | K19: ='P03'!$B$90 -> TRUE | L19: ='P03'!$B$91 -> TRUE | M19: ='P03'!$B$92 -> TRUE | N19: ='P03'!$B$93 -> TRUE | O19: ='P03'!$B$94 -> TRUE | P19: ='P03'!$B$95 -> TRUE | Q19: ='P03'!$B$96 -> TRUE | R19: ='P03'!$B$97 -> TRUE
A20: ='P04'!$B$3 -> P04 | B20: ='P04'!$B$299 -> TRUE | C20: ='P04'!$B$300 -> TRUE | D20: ='P04'!$B$301 -> TRUE | E20: ='P04'!$B$302 -> TRUE | F20: ='P04'!$B$303 -> TRUE | G20: ='P04'!$B$304 -> TRUE | H20: ='P04'!$B$305 -> TRUE | I20: ='P04'!$B$306 -> TRUE | J20: ='P04'!$B$307 -> TRUE | K20: ='P04'!$B$308 -> TRUE | L20: ='P04'!$B$309 -> TRUE | M20: ='P04'!$B$310 -> TRUE | N20: ='P04'!$B$311 -> TRUE | O20: ='P04'!$B$312 -> TRUE | P20: ='P04'!$B$313 -> TRUE | Q20: ='P04'!$B$314 -> TRUE | R20: ='P04'!$B$315 -> TRUE
A21: ='P05'!$B$3 -> P05 | B21: ='P05'!$B$94 -> TRUE | C21: ='P05'!$B$95 -> TRUE | D21: ='P05'!$B$96 -> TRUE | E21: ='P05'!$B$97 -> TRUE | F21: ='P05'!$B$98 -> TRUE | G21: ='P05'!$B$99 -> TRUE | H21: ='P05'!$B$100 -> TRUE | I21: ='P05'!$B$101 -> TRUE | J21: ='P05'!$B$102 -> TRUE | K21: ='P05'!$B$103 -> TRUE | L21: ='P05'!$B$104 -> TRUE | M21: ='P05'!$B$105 -> TRUE | N21: ='P05'!$B$106 -> TRUE | O21: ='P05'!$B$107 -> TRUE | P21: ='P05'!$B$108 -> TRUE | Q21: ='P05'!$B$109 -> TRUE | R21: ='P05'!$B$110 -> TRUE
A22: ='P06'!$B$3 -> P06 | B22: ='P06'!$B$199 -> TRUE | C22: ='P06'!$B$200 -> TRUE | D22: ='P06'!$B$201 -> TRUE | E22: ='P06'!$B$202 -> TRUE | F22: ='P06'!$B$203 -> TRUE | G22: ='P06'!$B$204 -> TRUE | H22: ='P06'!$B$205 -> TRUE | I22: ='P06'!$B$206 -> TRUE | J22: ='P06'!$B$207 -> TRUE | K22: ='P06'!$B$208 -> TRUE | L22: ='P06'!$B$209 -> TRUE | M22: ='P06'!$B$210 -> TRUE | N22: ='P06'!$B$211 -> TRUE | O22: ='P06'!$B$212 -> TRUE | P22: ='P06'!$B$213 -> TRUE | Q22: ='P06'!$B$214 -> TRUE | R22: ='P06'!$B$215 -> TRUE
A23: ='P07'!$B$3 -> P07 | B23: ='P07'!$B$238 -> TRUE | C23: ='P07'!$B$239 -> TRUE | D23: ='P07'!$B$240 -> TRUE | E23: ='P07'!$B$241 -> TRUE | F23: ='P07'!$B$242 -> TRUE | G23: ='P07'!$B$243 -> TRUE | H23: ='P07'!$B$244 -> TRUE | I23: ='P07'!$B$245 -> TRUE | J23: ='P07'!$B$246 -> TRUE | K23: ='P07'!$B$247 -> TRUE | L23: ='P07'!$B$248 -> TRUE | M23: ='P07'!$B$249 -> TRUE | N23: ='P07'!$B$250 -> TRUE | O23: ='P07'!$B$251 -> TRUE | P23: ='P07'!$B$252 -> TRUE | Q23: ='P07'!$B$253 -> TRUE | R23: ='P07'!$B$254 -> TRUE
A24: ='P08'!$B$3 -> P08 | B24: ='P08'!$B$128 -> TRUE | C24: ='P08'!$B$129 -> TRUE | D24: ='P08'!$B$130 -> TRUE | E24: ='P08'!$B$131 -> TRUE | F24: ='P08'!$B$132 -> TRUE | G24: ='P08'!$B$133 -> TRUE | H24: ='P08'!$B$134 -> TRUE | I24: ='P08'!$B$135 -> TRUE | J24: ='P08'!$B$136 -> TRUE | K24: ='P08'!$B$137 -> TRUE | L24: ='P08'!$B$138 -> TRUE | M24: ='P08'!$B$139 -> TRUE | N24: ='P08'!$B$140 -> TRUE | O24: ='P08'!$B$141 -> TRUE | P24: ='P08'!$B$142 -> TRUE | Q24: ='P08'!$B$143 -> TRUE | R24: ='P08'!$B$144 -> TRUE
A25: ='P09'!$B$3 -> P09 | B25: ='P09'!$B$560 -> TRUE | C25: ='P09'!$B$561 -> TRUE | D25: ='P09'!$B$562 -> TRUE | E25: ='P09'!$B$563 -> TRUE | F25: ='P09'!$B$564 -> TRUE | G25: ='P09'!$B$565 -> TRUE | H25: ='P09'!$B$566 -> TRUE | I25: ='P09'!$B$567 -> TRUE | J25: ='P09'!$B$568 -> TRUE | K25: ='P09'!$B$569 -> TRUE | L25: ='P09'!$B$570 -> TRUE | M25: ='P09'!$B$571 -> TRUE | N25: ='P09'!$B$572 -> TRUE | O25: ='P09'!$B$573 -> TRUE | P25: ='P09'!$B$574 -> TRUE | Q25: ='P09'!$B$575 -> TRUE | R25: ='P09'!$B$576 -> TRUE
A26: ='P10'!$B$3 -> P10 | B26: ='P10'!$B$141 -> TRUE | C26: ='P10'!$B$142 -> TRUE | D26: ='P10'!$B$143 -> TRUE | E26: ='P10'!$B$144 -> TRUE | F26: ='P10'!$B$145 -> TRUE | G26: ='P10'!$B$146 -> TRUE | H26: ='P10'!$B$147 -> TRUE | I26: ='P10'!$B$148 -> TRUE | J26: ='P10'!$B$149 -> TRUE | K26: ='P10'!$B$150 -> TRUE | L26: ='P10'!$B$151 -> TRUE | M26: ='P10'!$B$152 -> TRUE | N26: ='P10'!$B$153 -> TRUE | O26: ='P10'!$B$154 -> TRUE | P26: ='P10'!$B$155 -> TRUE | Q26: ='P10'!$B$156 -> TRUE | R26: ='P10'!$B$157 -> TRUE
A28: all_ok | B28: =AND(R17:R26) -> TRUE
A30: Totals by t (section 11.3), t = 0 .. 480: the sum over the ten policies of each Money and Count monthly column, a policy's values beyond its own rem_m read as zero
A31: t | B31: total_deaths | C31: total_lapses | D31: total_maturities | E31: total_pols_if | F31: total_premium_income | G31: total_commission | H31: total_maint_expense | I31: total_death_outgo | J31: total_claim_expense | K31: total_net_cf | L31: total_net_outgo | M31: total_pv_net_cf_t | N31: total_pv_premiums_t | O31: total_pv_commission_t | P31: total_pv_maint_expense_t | Q31: total_pv_death_outgo_t | R31: total_pv_claim_expense_t | S31: total_reserve | T31: total_reserve_floored
A32: 0 | E32: =IF($A32<='P01'!$B$17,INDEX('P01'!$M:$M,$A32+52),0)+IF($A32<='P02'!$B$17,INDEX('P02'!$M:$M,$A32+52),0)+IF($A32<='P03'!$B$17,INDEX('P03'!$M:$M,$A32+52),0)+IF($A32<='P04'!$B$17,INDEX('P04'!$M:$M,$A32+52),0)+IF($A32<='P05'!$B$17,INDEX('P05'!$M:$M,$A32+52),0)+IF($A32<='P06'!$B$17,INDEX('P06'!$M:$M,$A32+52),0)+IF($A32<='P07'!$B$17,INDEX('P07'!$M:$M,$A32+52),0)+IF($A32<='P08'!$B$17,INDEX('P08'!$M:$M,$A32+52),0)+IF($A32<='P09'!$B$17,INDEX('P09'!$M:$M,$A32+52),0)+IF($A32<='P10'!$B$17,INDEX('P10'!$M:$M,$A32+52),0) -> 11.5 | S32: =IF($A32<='P01'!$B$17,INDEX('P01'!$AG:$AG,$A32+52),0)+IF($A32<='P02'!$B$17,INDEX('P02'!$AG:$AG,$A32+52),0)+IF($A32<='P03'!$B$17,INDEX('P03'!$AG:$AG,$A32+52),0)+IF($A32<='P04'!$B$17,INDEX('P04'!$AG:$AG,$A32+52),0)+IF($A32<='P05'!$B$17,INDEX('P05'!$AG:$AG,$A32+52),0)+IF($A32<='P06'!$B$17,INDEX('P06'!$AG:$AG,$A32+52),0)+IF($A32<='P07'!$B$17,INDEX('P07'!$AG:$AG,$A32+52),0)+IF($A32<='P08'!$B$17,INDEX('P08'!$AG:$AG,$A32+52),0)+IF($A32<='P09'!$B$17,INDEX('P09'!$AG:$AG,$A32+52),0)+IF($A32<='P10'!$B$17,INDEX('P10'!$AG:$AG,$A32+52),0) -> 11043.079 | T32: =IF($A32<='P01'!$B$17,INDEX('P01'!$AI:$AI,$A32+52),0)+IF($A32<='P02'!$B$17,INDEX('P02'!$AI:$AI,$A32+52),0)+IF($A32<='P03'!$B$17,INDEX('P03'!$AI:$AI,$A32+52),0)+IF($A32<='P04'!$B$17,INDEX('P04'!$AI:$AI,$A32+52),0)+IF($A32<='P05'!$B$17,INDEX('P05'!$AI:$AI,$A32+52),0)+IF($A32<='P06'!$B$17,INDEX('P06'!$AI:$AI,$A32+52),0)+IF($A32<='P07'!$B$17,INDEX('P07'!$AI:$AI,$A32+52),0)+IF($A32<='P08'!$B$17,INDEX('P08'!$AI:$AI,$A32+52),0)+IF($A32<='P09'!$B$17,INDEX('P09'!$AI:$AI,$A32+52),0)+IF($A32<='P10'!$B$17,INDEX('P10'!$AI:$AI,$A32+52),0) -> 15417.57
A33: 1 | B33: =IF($A33<='P01'!$B$17,INDEX('P01'!$J:$J,$A33+52),0)+IF($A33<='P02'!$B$17,INDEX('P02'!$J:$J,$A33+52),0)+IF($A33<='P03'!$B$17,INDEX('P03'!$J:$J,$A33+52),0)+IF($A33<='P04'!$B$17,INDEX('P04'!$J:$J,$A33+52),0)+IF($A33<='P05'!$B$17,INDEX('P05'!$J:$J,$A33+52),0)+IF($A33<='P06'!$B$17,INDEX('P06'!$J:$J,$A33+52),0)+IF($A33<='P07'!$B$17,INDEX('P07'!$J:$J,$A33+52),0)+IF($A33<='P08'!$B$17,INDEX('P08'!$J:$J,$A33+52),0)+IF($A33<='P09'!$B$17,INDEX('P09'!$J:$J,$A33+52),0)+IF($A33<='P10'!$B$17,INDEX('P10'!$J:$J,$A33+52),0) -> 0.0022653818 | C33: =IF($A33<='P01'!$B$17,INDEX('P01'!$K:$K,$A33+52),0)+IF($A33<='P02'!$B$17,INDEX('P02'!$K:$K,$A33+52),0)+IF($A33<='P03'!$B$17,INDEX('P03'!$K:$K,$A33+52),0)+IF($A33<='P04'!$B$17,INDEX('P04'!$K:$K,$A33+52),0)+IF($A33<='P05'!$B$17,INDEX('P05'!$K:$K,$A33+52),0)+IF($A33<='P06'!$B$17,INDEX('P06'!$K:$K,$A33+52),0)+IF($A33<='P07'!$B$17,INDEX('P07'!$K:$K,$A33+52),0)+IF($A33<='P08'!$B$17,INDEX('P08'!$K:$K,$A33+52),0)+IF($A33<='P09'!$B$17,INDEX('P09'!$K:$K,$A33+52),0)+IF($A33<='P10'!$B$17,INDEX('P10'!$K:$K,$A33+52),0) -> 0.07021824 | D33: =IF($A33<='P01'!$B$17,INDEX('P01'!$L:$L,$A33+52),0)+IF($A33<='P02'!$B$17,INDEX('P02'!$L:$L,$A33+52),0)+IF($A33<='P03'!$B$17,INDEX('P03'!$L:$L,$A33+52),0)+IF($A33<='P04'!$B$17,INDEX('P04'!$L:$L,$A33+52),0)+IF($A33<='P05'!$B$17,INDEX('P05'!$L:$L,$A33+52),0)+IF($A33<='P06'!$B$17,INDEX('P06'!$L:$L,$A33+52),0)+IF($A33<='P07'!$B$17,INDEX('P07'!$L:$L,$A33+52),0)+IF($A33<='P08'!$B$17,INDEX('P08'!$L:$L,$A33+52),0)+IF($A33<='P09'!$B$17,INDEX('P09'!$L:$L,$A33+52),0)+IF($A33<='P10'!$B$17,INDEX('P10'!$L:$L,$A33+52),0) -> 0.99617739 | E33: =IF($A33<='P01'!$B$17,INDEX('P01'!$M:$M,$A33+52),0)+IF($A33<='P02'!$B$17,INDEX('P02'!$M:$M,$A33+52),0)+IF($A33<='P03'!$B$17,INDEX('P03'!$M:$M,$A33+52),0)+IF($A33<='P04'!$B$17,INDEX('P04'!$M:$M,$A33+52),0)+IF($A33<='P05'!$B$17,INDEX('P05'!$M:$M,$A33+52),0)+IF($A33<='P06'!$B$17,INDEX('P06'!$M:$M,$A33+52),0)+IF($A33<='P07'!$B$17,INDEX('P07'!$M:$M,$A33+52),0)+IF($A33<='P08'!$B$17,INDEX('P08'!$M:$M,$A33+52),0)+IF($A33<='P09'!$B$17,INDEX('P09'!$M:$M,$A33+52),0)+IF($A33<='P10'!$B$17,INDEX('P10'!$M:$M,$A33+52),0) -> 10.431339 | F33: =IF($A33<='P01'!$B$17,INDEX('P01'!$R:$R,$A33+52),0)+IF($A33<='P02'!$B$17,INDEX('P02'!$R:$R,$A33+52),0)+IF($A33<='P03'!$B$17,INDEX('P03'!$R:$R,$A33+52),0)+IF($A33<='P04'!$B$17,INDEX('P04'!$R:$R,$A33+52),0)+IF($A33<='P05'!$B$17,INDEX('P05'!$R:$R,$A33+52),0)+IF($A33<='P06'!$B$17,INDEX('P06'!$R:$R,$A33+52),0)+IF($A33<='P07'!$B$17,INDEX('P07'!$R:$R,$A33+52),0)+IF($A33<='P08'!$B$17,INDEX('P08'!$R:$R,$A33+52),0)+IF($A33<='P09'!$B$17,INDEX('P09'!$R:$R,$A33+52),0)+IF($A33<='P10'!$B$17,INDEX('P10'!$R:$R,$A33+52),0) -> 690.495 | G33: =IF($A33<='P01'!$B$17,INDEX('P01'!$S:$S,$A33+52),0)+IF($A33<='P02'!$B$17,INDEX('P02'!$S:$S,$A33+52),0)+IF($A33<='P03'!$B$17,INDEX('P03'!$S:$S,$A33+52),0)+IF($A33<='P04'!$B$17,INDEX('P04'!$S:$S,$A33+52),0)+IF($A33<='P05'!$B$17,INDEX('P05'!$S:$S,$A33+52),0)+IF($A33<='P06'!$B$17,INDEX('P06'!$S:$S,$A33+52),0)+IF($A33<='P07'!$B$17,INDEX('P07'!$S:$S,$A33+52),0)+IF($A33<='P08'!$B$17,INDEX('P08'!$S:$S,$A33+52),0)+IF($A33<='P09'!$B$17,INDEX('P09'!$S:$S,$A33+52),0)+IF($A33<='P10'!$B$17,INDEX('P10'!$S:$S,$A33+52),0) -> 46.0335 | H33: =IF($A33<='P01'!$B$17,INDEX('P01'!$T:$T,$A33+52),0)+IF($A33<='P02'!$B$17,INDEX('P02'!$T:$T,$A33+52),0)+IF($A33<='P03'!$B$17,INDEX('P03'!$T:$T,$A33+52),0)+IF($A33<='P04'!$B$17,INDEX('P04'!$T:$T,$A33+52),0)+IF($A33<='P05'!$B$17,INDEX('P05'!$T:$T,$A33+52),0)+IF($A33<='P06'!$B$17,INDEX('P06'!$T:$T,$A33+52),0)+IF($A33<='P07'!$B$17,INDEX('P07'!$T:$T,$A33+52),0)+IF($A33<='P08'!$B$17,INDEX('P08'!$T:$T,$A33+52),0)+IF($A33<='P09'!$B$17,INDEX('P09'!$T:$T,$A33+52),0)+IF($A33<='P10'!$B$17,INDEX('P10'!$T:$T,$A33+52),0) -> 57.641811 | I33: =IF($A33<='P01'!$B$17,INDEX('P01'!$U:$U,$A33+52),0)+IF($A33<='P02'!$B$17,INDEX('P02'!$U:$U,$A33+52),0)+IF($A33<='P03'!$B$17,INDEX('P03'!$U:$U,$A33+52),0)+IF($A33<='P04'!$B$17,INDEX('P04'!$U:$U,$A33+52),0)+IF($A33<='P05'!$B$17,INDEX('P05'!$U:$U,$A33+52),0)+IF($A33<='P06'!$B$17,INDEX('P06'!$U:$U,$A33+52),0)+IF($A33<='P07'!$B$17,INDEX('P07'!$U:$U,$A33+52),0)+IF($A33<='P08'!$B$17,INDEX('P08'!$U:$U,$A33+52),0)+IF($A33<='P09'!$B$17,INDEX('P09'!$U:$U,$A33+52),0)+IF($A33<='P10'!$B$17,INDEX('P10'!$U:$U,$A33+52),0) -> 491.45203 | J33: =IF($A33<='P01'!$B$17,INDEX('P01'!$V:$V,$A33+52),0)+IF($A33<='P02'!$B$17,INDEX('P02'!$V:$V,$A33+52),0)+IF($A33<='P03'!$B$17,INDEX('P03'!$V:$V,$A33+52),0)+IF($A33<='P04'!$B$17,INDEX('P04'!$V:$V,$A33+52),0)+IF($A33<='P05'!$B$17,INDEX('P05'!$V:$V,$A33+52),0)+IF($A33<='P06'!$B$17,INDEX('P06'!$V:$V,$A33+52),0)+IF($A33<='P07'!$B$17,INDEX('P07'!$V:$V,$A33+52),0)+IF($A33<='P08'!$B$17,INDEX('P08'!$V:$V,$A33+52),0)+IF($A33<='P09'!$B$17,INDEX('P09'!$V:$V,$A33+52),0)+IF($A33<='P10'!$B$17,INDEX('P10'!$V:$V,$A33+52),0) -> 0.56774221 | K33: =IF($A33<='P01'!$B$17,INDEX('P01'!$W:$W,$A33+52),0)+IF($A33<='P02'!$B$17,INDEX('P02'!$W:$W,$A33+52),0)+IF($A33<='P03'!$B$17,INDEX('P03'!$W:$W,$A33+52),0)+IF($A33<='P04'!$B$17,INDEX('P04'!$W:$W,$A33+52),0)+IF($A33<='P05'!$B$17,INDEX('P05'!$W:$W,$A33+52),0)+IF($A33<='P06'!$B$17,INDEX('P06'!$W:$W,$A33+52),0)+IF($A33<='P07'!$B$17,INDEX('P07'!$W:$W,$A33+52),0)+IF($A33<='P08'!$B$17,INDEX('P08'!$W:$W,$A33+52),0)+IF($A33<='P09'!$B$17,INDEX('P09'!$W:$W,$A33+52),0)+IF($A33<='P10'!$B$17,INDEX('P10'!$W:$W,$A33+52),0) -> 94.799917 | L33: =IF($A33<='P01'!$B$17,INDEX('P01'!$X:$X,$A33+52),0)+IF($A33<='P02'!$B$17,INDEX('P02'!$X:$X,$A33+52),0)+IF($A33<='P03'!$B$17,INDEX('P03'!$X:$X,$A33+52),0)+IF($A33<='P04'!$B$17,INDEX('P04'!$X:$X,$A33+52),0)+IF($A33<='P05'!$B$17,INDEX('P05'!$X:$X,$A33+52),0)+IF($A33<='P06'!$B$17,INDEX('P06'!$X:$X,$A33+52),0)+IF($A33<='P07'!$B$17,INDEX('P07'!$X:$X,$A33+52),0)+IF($A33<='P08'!$B$17,INDEX('P08'!$X:$X,$A33+52),0)+IF($A33<='P09'!$B$17,INDEX('P09'!$X:$X,$A33+52),0)+IF($A33<='P10'!$B$17,INDEX('P10'!$X:$X,$A33+52),0) -> -96.909716 | M33: =IF($A33<='P01'!$B$17,INDEX('P01'!$AA:$AA,$A33+52),0)+IF($A33<='P02'!$B$17,INDEX('P02'!$AA:$AA,$A33+52),0)+IF($A33<='P03'!$B$17,INDEX('P03'!$AA:$AA,$A33+52),0)+IF($A33<='P04'!$B$17,INDEX('P04'!$AA:$AA,$A33+52),0)+IF($A33<='P05'!$B$17,INDEX('P05'!$AA:$AA,$A33+52),0)+IF($A33<='P06'!$B$17,INDEX('P06'!$AA:$AA,$A33+52),0)+IF($A33<='P07'!$B$17,INDEX('P07'!$AA:$AA,$A33+52),0)+IF($A33<='P08'!$B$17,INDEX('P08'!$AA:$AA,$A33+52),0)+IF($A33<='P09'!$B$17,INDEX('P09'!$AA:$AA,$A33+52),0)+IF($A33<='P10'!$B$17,INDEX('P10'!$AA:$AA,$A33+52),0) -> 96.593494 | N33: =IF($A33<='P01'!$B$17,INDEX('P01'!$AB:$AB,$A33+52),0)+IF($A33<='P02'!$B$17,INDEX('P02'!$AB:$AB,$A33+52),0)+IF($A33<='P03'!$B$17,INDEX('P03'!$AB:$AB,$A33+52),0)+IF($A33<='P04'!$B$17,INDEX('P04'!$AB:$AB,$A33+52),0)+IF($A33<='P05'!$B$17,INDEX('P05'!$AB:$AB,$A33+52),0)+IF($A33<='P06'!$B$17,INDEX('P06'!$AB:$AB,$A33+52),0)+IF($A33<='P07'!$B$17,INDEX('P07'!$AB:$AB,$A33+52),0)+IF($A33<='P08'!$B$17,INDEX('P08'!$AB:$AB,$A33+52),0)+IF($A33<='P09'!$B$17,INDEX('P09'!$AB:$AB,$A33+52),0)+IF($A33<='P10'!$B$17,INDEX('P10'!$AB:$AB,$A33+52),0) -> 690.495 | O33: =IF($A33<='P01'!$B$17,INDEX('P01'!$AC:$AC,$A33+52),0)+IF($A33<='P02'!$B$17,INDEX('P02'!$AC:$AC,$A33+52),0)+IF($A33<='P03'!$B$17,INDEX('P03'!$AC:$AC,$A33+52),0)+IF($A33<='P04'!$B$17,INDEX('P04'!$AC:$AC,$A33+52),0)+IF($A33<='P05'!$B$17,INDEX('P05'!$AC:$AC,$A33+52),0)+IF($A33<='P06'!$B$17,INDEX('P06'!$AC:$AC,$A33+52),0)+IF($A33<='P07'!$B$17,INDEX('P07'!$AC:$AC,$A33+52),0)+IF($A33<='P08'!$B$17,INDEX('P08'!$AC:$AC,$A33+52),0)+IF($A33<='P09'!$B$17,INDEX('P09'!$AC:$AC,$A33+52),0)+IF($A33<='P10'!$B$17,INDEX('P10'!$AC:$AC,$A33+52),0) -> 46.0335 | P33: =IF($A33<='P01'!$B$17,INDEX('P01'!$AD:$AD,$A33+52),0)+IF($A33<='P02'!$B$17,INDEX('P02'!$AD:$AD,$A33+52),0)+IF($A33<='P03'!$B$17,INDEX('P03'!$AD:$AD,$A33+52),0)+IF($A33<='P04'!$B$17,INDEX('P04'!$AD:$AD,$A33+52),0)+IF($A33<='P05'!$B$17,INDEX('P05'!$AD:$AD,$A33+52),0)+IF($A33<='P06'!$B$17,INDEX('P06'!$AD:$AD,$A33+52),0)+IF($A33<='P07'!$B$17,INDEX('P07'!$AD:$AD,$A33+52),0)+IF($A33<='P08'!$B$17,INDEX('P08'!$AD:$AD,$A33+52),0)+IF($A33<='P09'!$B$17,INDEX('P09'!$AD:$AD,$A33+52),0)+IF($A33<='P10'!$B$17,INDEX('P10'!$AD:$AD,$A33+52),0) -> 57.453722 | Q33: =IF($A33<='P01'!$B$17,INDEX('P01'!$AE:$AE,$A33+52),0)+IF($A33<='P02'!$B$17,INDEX('P02'!$AE:$AE,$A33+52),0)+IF($A33<='P03'!$B$17,INDEX('P03'!$AE:$AE,$A33+52),0)+IF($A33<='P04'!$B$17,INDEX('P04'!$AE:$AE,$A33+52),0)+IF($A33<='P05'!$B$17,INDEX('P05'!$AE:$AE,$A33+52),0)+IF($A33<='P06'!$B$17,INDEX('P06'!$AE:$AE,$A33+52),0)+IF($A33<='P07'!$B$17,INDEX('P07'!$AE:$AE,$A33+52),0)+IF($A33<='P08'!$B$17,INDEX('P08'!$AE:$AE,$A33+52),0)+IF($A33<='P09'!$B$17,INDEX('P09'!$AE:$AE,$A33+52),0)+IF($A33<='P10'!$B$17,INDEX('P10'!$AE:$AE,$A33+52),0) -> 489.84839 | R33: =IF($A33<='P01'!$B$17,INDEX('P01'!$AF:$AF,$A33+52),0)+IF($A33<='P02'!$B$17,INDEX('P02'!$AF:$AF,$A33+52),0)+IF($A33<='P03'!$B$17,INDEX('P03'!$AF:$AF,$A33+52),0)+IF($A33<='P04'!$B$17,INDEX('P04'!$AF:$AF,$A33+52),0)+IF($A33<='P05'!$B$17,INDEX('P05'!$AF:$AF,$A33+52),0)+IF($A33<='P06'!$B$17,INDEX('P06'!$AF:$AF,$A33+52),0)+IF($A33<='P07'!$B$17,INDEX('P07'!$AF:$AF,$A33+52),0)+IF($A33<='P08'!$B$17,INDEX('P08'!$AF:$AF,$A33+52),0)+IF($A33<='P09'!$B$17,INDEX('P09'!$AF:$AF,$A33+52),0)+IF($A33<='P10'!$B$17,INDEX('P10'!$AF:$AF,$A33+52),0) -> 0.56588963 | S33: =IF($A33<='P01'!$B$17,INDEX('P01'!$AG:$AG,$A33+52),0)+IF($A33<='P02'!$B$17,INDEX('P02'!$AG:$AG,$A33+52),0)+IF($A33<='P03'!$B$17,INDEX('P03'!$AG:$AG,$A33+52),0)+IF($A33<='P04'!$B$17,INDEX('P04'!$AG:$AG,$A33+52),0)+IF($A33<='P05'!$B$17,INDEX('P05'!$AG:$AG,$A33+52),0)+IF($A33<='P06'!$B$17,INDEX('P06'!$AG:$AG,$A33+52),0)+IF($A33<='P07'!$B$17,INDEX('P07'!$AG:$AG,$A33+52),0)+IF($A33<='P08'!$B$17,INDEX('P08'!$AG:$AG,$A33+52),0)+IF($A33<='P09'!$B$17,INDEX('P09'!$AG:$AG,$A33+52),0)+IF($A33<='P10'!$B$17,INDEX('P10'!$AG:$AG,$A33+52),0) -> 11176.141 | T33: =IF($A33<='P01'!$B$17,INDEX('P01'!$AI:$AI,$A33+52),0)+IF($A33<='P02'!$B$17,INDEX('P02'!$AI:$AI,$A33+52),0)+IF($A33<='P03'!$B$17,INDEX('P03'!$AI:$AI,$A33+52),0)+IF($A33<='P04'!$B$17,INDEX('P04'!$AI:$AI,$A33+52),0)+IF($A33<='P05'!$B$17,INDEX('P05'!$AI:$AI,$A33+52),0)+IF($A33<='P06'!$B$17,INDEX('P06'!$AI:$AI,$A33+52),0)+IF($A33<='P07'!$B$17,INDEX('P07'!$AI:$AI,$A33+52),0)+IF($A33<='P08'!$B$17,INDEX('P08'!$AI:$AI,$A33+52),0)+IF($A33<='P09'!$B$17,INDEX('P09'!$AI:$AI,$A33+52),0)+IF($A33<='P10'!$B$17,INDEX('P10'!$AI:$AI,$A33+52),0) -> 15457.478
