Workbook
Name all_ok: checks!$B$22
Name cif: inputs!$AH$4:$FC$104
Name cif_age: inputs!$AF$4:$AF$104
Name cif_year: inputs!$AH$1:$FC$1
Name cpi_rec_u: inputs!$X$2:$X$527
Name cpi_u: inputs!$AA$2:$AA$517
Name curve_t: inputs!$L$2:$L$503
Name d_L: inputs!$U$2:$U$503
Name I_act: inputs!$AB$2:$AB$517
Name I_cur: inputs!$AD$2:$AD$517
Name I_L: inputs!$AC$2:$AC$517
Name I_rec: inputs!$Y$2:$Y$527
Name j_L: inputs!$V$2:$V$503
Name mort_age: inputs!$F$2:$F$102
Name mort_v1_F: inputs!$H$2:$H$102
Name mort_v1_M: inputs!$G$2:$G$102
Name mort_v2_F: inputs!$J$2:$J$102
Name mort_v2_M: inputs!$I$2:$I$102
Name P_cur: inputs!$S$2:$S$503
Name P_L: inputs!$T$2:$T$503
Name P_rec: inputs!$P$2:$P$503

Sheet inputs
A1: input | B1: value | C1: note | F1: age | G1: mort_base_v1(M, x) | H1: mort_base_v1(F, x) | I1: mort_base_v2(M, x) | J1: mort_base_v2(F, x) | L1: t | M1: s = t / 12 | N1: z_rec(s) | O1: rf_df_rec(t) | P1: P_rec(t) | Q1: z_cur(s) | R1: rf_df_cur(t) | S1: P_cur(t) | T1: P_L(t) | U1: d_L(t) | V1: j_L(t) | X1: u (relative to V_rec) | Y1: I_rec(u) | AA1: u (relative to V) | AB1: I_act(u) | AC1: I_L(u) | AD1: I_cur(u) | AF1: age (rows) by year (columns) | AG1: g(x) | AH1: 2025 | AI1: 2026 | AJ1: 2027 | AK1: 2028 | AL1: 2029 | AM1: 2030 | AN1: 2031 | AO1: 2032 | AP1: 2033 | AQ1: 2034 | AR1: 2035 | AS1: 2036 | AT1: 2037 | AU1: 2038 | AV1: 2039 | AW1: 2040 | AX1: 2041 | AY1: 2042 | AZ1: 2043 | BA1: 2044 | BB1: 2045 | BC1: 2046 | BD1: 2047 | BE1: 2048 | BF1: 2049 | BG1: 2050 | BH1: 2051 | BI1: 2052 | BJ1: 2053 | BK1: 2054 | BL1: 2055 | BM1: 2056 | BN1: 2057 | BO1: 2058 | BP1: 2059 | BQ1: 2060 | BR1: 2061 | BS1: 2062 | BT1: 2063 | BU1: 2064 | BV1: 2065 | BW1: 2066 | BX1: 2067 | BY1: 2068 | BZ1: 2069 | CA1: 2070 | CB1: 2071 | CC1: 2072 | CD1: 2073 | CE1: 2074 | CF1: 2075 | CG1: 2076 | CH1: 2077 | CI1: 2078 | CJ1: 2079 | CK1: 2080 | CL1: 2081 | CM1: 2082 | CN1: 2083 | CO1: 2084 | CP1: 2085 | CQ1: 2086 | CR1: 2087 | CS1: 2088 | CT1: 2089 | CU1: 2090 | CV1: 2091 | CW1: 2092 | CX1: 2093 | CY1: 2094 | CZ1: 2095 | DA1: 2096 | DB1: 2097 | DC1: 2098 | DD1: 2099 | DE1: 2100 | DF1: 2101 | DG1: 2102 | DH1: 2103 | DI1: 2104 | DJ1: 2105 | DK1: 2106 | DL1: 2107 | DM1: 2108 | DN1: 2109 | DO1: 2110 | DP1: 2111 | DQ1: 2112 | DR1: 2113 | DS1: 2114 | DT1: 2115 | DU1: 2116 | DV1: 2117 | DW1: 2118 | DX1: 2119 | DY1: 2120 | DZ1: 2121 | EA1: 2122 | EB1: 2123 | EC1: 2124 | ED1: 2125 | EE1: 2126 | EF1: 2127 | EG1: 2128 | EH1: 2129 | EI1: 2130 | EJ1: 2131 | EK1: 2132 | EL1: 2133 | EM1: 2134 | EN1: 2135 | EO1: 2136 | EP1: 2137 | EQ1: 2138 | ER1: 2139 | ES1: 2140 | ET1: 2141 | EU1: 2142 | EV1: 2143 | EW1: 2144 | EX1: 2145 | EY1: 2146 | EZ1: 2147 | FA1: 2148 | FB1: 2149 | FC1: 2150
A2: 3.1 Run settings | F2: 20 | G2: =1-EXP(-inputs!$B$35-inputs!$B$36*inputs!$B$37^$F2*(inputs!$B$37-1)/LN(inputs!$B$37)) -> 0.00024963903 | H2: =1-EXP(-inputs!$B$35-inputs!$B$36*inputs!$B$37^($F2-4)*(inputs!$B$37-1)/LN(inputs!$B$37)) -> 0.0002385605 | I2: =0.96*G2 -> 0.00023965347 | J2: =0.96*H2 -> 0.00022901808 | L2: 0 | M2: =L2/12 -> 0 | N2: =0.04-0.015*EXP(-M2/10) -> 0.025 | O2: =EXP(-N2*M2) -> 1 | P2: =O2*EXP(-inputs!$B$27*L2/12) -> 1 | Q2: =0.045-0.015*EXP(-M2/10) -> 0.03 | R2: =EXP(-Q2*M2) -> 1 | S2: =R2*EXP(-inputs!$B$27*L2/12) -> 1 | T2: =INDEX(P_rec,MATCH(inputs!$B$13+L2,curve_t,0))/INDEX(P_rec,MATCH(inputs!$B$13,curve_t,0)) -> 1 | X2: -24 | Y2: =IF(X2<=0,100*1.04^(X2/12),100*1.025^(X2/12)) -> 92.455621 | AA2: -26 | AB2: =IF(AA2<=-13,100*1.04^((AA2+12)/12),100.1*1.032^((AA2+12)/12)) -> 95.527359 | AC2: =AB2 -> 95.527359 | AD2: =AB2 -> 95.527359 | AF2: h(y) = min(1, (y - 2026) / 20) | AI2: =MIN(1,(AI$1-2026)/20) -> 0 | AJ2: =MIN(1,(AJ$1-2026)/20) -> 0.05 | AK2: =MIN(1,(AK$1-2026)/20) -> 0.1 | AL2: =MIN(1,(AL$1-2026)/20) -> 0.15 | AM2: =MIN(1,(AM$1-2026)/20) -> 0.2 | AN2: =MIN(1,(AN$1-2026)/20) -> 0.25 | AO2: =MIN(1,(AO$1-2026)/20) -> 0.3 | AP2: =MIN(1,(AP$1-2026)/20) -> 0.35 | ... FC2: =MIN(1,(FC$1-2026)/20) -> 1
A3: variant | B3: O | F3: 21 | G3: =1-EXP(-inputs!$B$35-inputs!$B$36*inputs!$B$37^$F3*(inputs!$B$37-1)/LN(inputs!$B$37)) -> 0.00025331721 | H3: =1-EXP(-inputs!$B$35-inputs!$B$36*inputs!$B$37^($F3-4)*(inputs!$B$37-1)/LN(inputs!$B$37)) -> 0.00024086498 | I3: =0.96*G3 -> 0.00024318452 | J3: =0.96*H3 -> 0.00023123038 | L3: 1 | M3: =L3/12 -> 0.083333333 | N3: =0.04-0.015*EXP(-M3/10) -> 0.025124481 | O3: =EXP(-N3*M3) -> 0.99790848 | P3: =O3*EXP(-inputs!$B$27*L3/12) -> 0.99749277 | Q3: =0.045-0.015*EXP(-M3/10) -> 0.030124481 | R3: =EXP(-Q3*M3) -> 0.99749277 | S3: =R3*EXP(-inputs!$B$27*L3/12) -> 0.99707724 | T3: =INDEX(P_rec,MATCH(inputs!$B$13+L3,curve_t,0))/INDEX(P_rec,MATCH(inputs!$B$13,curve_t,0)) -> 0.99726278 | U3: =T3/T2 -> 0.99726278 | V3: =T2/T3-1 -> 0.0027447341 | X3: -23 | Y3: =IF(X3<=0,100*1.04^(X3/12),100*1.025^(X3/12)) -> 92.758297 | AA3: -25 | AB3: =IF(AA3<=-13,100*1.04^((AA3+12)/12),100.1*1.032^((AA3+12)/12)) -> 95.840091 | AC3: =AB3 -> 95.840091 | AD3: =AB3 -> 95.840091 | AF3: w(h) = 1 - 3 h^2 + 2 h^3 | AI3: =1-3*AI$2^2+2*AI$2^3 -> 1 | AJ3: =1-3*AJ$2^2+2*AJ$2^3 -> 0.99275 | AK3: =1-3*AK$2^2+2*AK$2^3 -> 0.972 | AL3: =1-3*AL$2^2+2*AL$2^3 -> 0.93925 | AM3: =1-3*AM$2^2+2*AM$2^3 -> 0.896 | AN3: =1-3*AN$2^2+2*AN$2^3 -> 0.84375 | AO3: =1-3*AO$2^2+2*AO$2^3 -> 0.784 | AP3: =1-3*AP$2^2+2*AP$2^3 -> 0.71825 | ... FC3: =1-3*FC$2^2+2*FC$2^3 -> 0
F4: 22 | G4: =1-EXP(-inputs!$B$35-inputs!$B$36*inputs!$B$37^$F4*(inputs!$B$37-1)/LN(inputs!$B$37)) -> 0.00025745146 | H4: =1-EXP(-inputs!$B$35-inputs!$B$36*inputs!$B$37^($F4-4)*(inputs!$B$37-1)/LN(inputs!$B$37)) -> 0.00024345521 | I4: =0.96*G4 -> 0.00024715341 | J4: =0.96*H4 -> 0.000233717 | L4: 2 | M4: =L4/12 -> 0.16666667 | N4: =0.04-0.015*EXP(-M4/10) -> 0.025247928 | O4: =EXP(-N4*M4) -> 0.99580085 | P4: =O4*EXP(-inputs!$B$27*L4/12) -> 0.99497136 | Q4: =0.045-0.015*EXP(-M4/10) -> 0.030247928 | R4: =EXP(-Q4*M4) -> 0.99497136 | S4: =R4*EXP(-inputs!$B$27*L4/12) -> 0.99414257 | T4: =INDEX(P_rec,MATCH(inputs!$B$13+L4,curve_t,0))/INDEX(P_rec,MATCH(inputs!$B$13,curve_t,0)) -> 0.99451547 | U4: =T4/T3 -> 0.99724515 | V4: =T3/T4-1 -> 0.0027624647 | X4: -22 | Y4: =IF(X4<=0,100*1.04^(X4/12),100*1.025^(X4/12)) -> 93.061963 | AA4: -24 | AB4: =IF(AA4<=-13,100*1.04^((AA4+12)/12),100.1*1.032^((AA4+12)/12)) -> 96.153846 | AC4: =AB4 -> 96.153846 | AD4: =AB4 -> 96.153846 | AF4: 20 | AG4: =IF($AF4<=85,1,IF($AF4<110,(110-$AF4)/25,0)) -> 1 | AH4: =1 -> 1 | AI4: =AH4*(1-$AG4*(0.01+0.01*AI$3)) -> 0.98 | AJ4: =AI4*(1-$AG4*(0.01+0.01*AJ$3)) -> 0.96047105 | AK4: =AJ4*(1-$AG4*(0.01+0.01*AK$3)) -> 0.94153056 | AL4: =AK4*(1-$AG4*(0.01+0.01*AL$3)) -> 0.92327193 | AM4: =AL4*(1-$AG4*(0.01+0.01*AM$3)) -> 0.90576669 | AN4: =AM4*(1-$AG4*(0.01+0.01*AN$3)) -> 0.88906662 | AO4: =AN4*(1-$AG4*(0.01+0.01*AO$3)) -> 0.87320567 | AP4: =AO4*(1-$AG4*(0.01+0.01*AP$3)) -> 0.85820182 | ... FC4: =FB4*(1-$AG4*(0.01+0.01*FC$3)) -> 0.25595353
F5: 23 | G5: =1-EXP(-inputs!$B$35-inputs!$B$36*inputs!$B$37^$F5*(inputs!$B$37-1)/LN(inputs!$B$37)) -> 0.00026209835 | H5: =1-EXP(-inputs!$B$35-inputs!$B$36*inputs!$B$37^($F5-4)*(inputs!$B$37-1)/LN(inputs!$B$37)) -> 0.00024636662 | I5: =0.96*G5 -> 0.00025161441 | J5: =0.96*H5 -> 0.00023651195 | L5: 3 | M5: =L5/12 -> 0.25 | N5: =0.04-0.015*EXP(-M5/10) -> 0.025370351 | O5: =EXP(-N5*M5) -> 0.99367748 | P5: =O5*EXP(-inputs!$B$27*L5/12) -> 0.99243616 | Q5: =0.045-0.015*EXP(-M5/10) -> 0.030370351 | R5: =EXP(-Q5*M5) -> 0.99243616 | S5: =R5*EXP(-inputs!$B$27*L5/12) -> 0.99119639 | T5: =INDEX(P_rec,MATCH(inputs!$B$13+L5,curve_t,0))/INDEX(P_rec,MATCH(inputs!$B$13,curve_t,0)) -> 0.99175841 | U5: =T5/T4 -> 0.99722774 | V5: =T4/T5-1 -> 0.002779971 | X5: -21 | Y5: =IF(X5<=0,100*1.04^(X5/12),100*1.025^(X5/12)) -> 93.366624 | AA5: -23 | AB5: =IF(AA5<=-13,100*1.04^((AA5+12)/12),100.1*1.032^((AA5+12)/12)) -> 96.468629 | AC5: =AB5 -> 96.468629 | AD5: =AB5 -> 96.468629 | AF5: 21 | AG5: =IF($AF5<=85,1,IF($AF5<110,(110-$AF5)/25,0)) -> 1 | AH5: =1 -> 1 | AI5: =AH5*(1-$AG5*(0.01+0.01*AI$3)) -> 0.98 | AJ5: =AI5*(1-$AG5*(0.01+0.01*AJ$3)) -> 0.96047105 | AK5: =AJ5*(1-$AG5*(0.01+0.01*AK$3)) -> 0.94153056 | AL5: =AK5*(1-$AG5*(0.01+0.01*AL$3)) -> 0.92327193 | AM5: =AL5*(1-$AG5*(0.01+0.01*AM$3)) -> 0.90576669 | AN5: =AM5*(1-$AG5*(0.01+0.01*AN$3)) -> 0.88906662 | AO5: =AN5*(1-$AG5*(0.01+0.01*AO$3)) -> 0.87320567 | AP5: =AO5*(1-$AG5*(0.01+0.01*AP$3)) -> 0.85820182 | ... FC5: =FB5*(1-$AG5*(0.01+0.01*FC$3)) -> 0.25595353
F6: 24 | G6: =1-EXP(-inputs!$B$35-inputs!$B$36*inputs!$B$37^$F6*(inputs!$B$37-1)/LN(inputs!$B$37)) -> 0.00026732142 | H6: =1-EXP(-inputs!$B$35-inputs!$B$36*inputs!$B$37^($F6-4)*(inputs!$B$37-1)/LN(inputs!$B$37)) -> 0.00024963903 | I6: =0.96*G6 -> 0.00025662856 | J6: =0.96*H6 -> 0.00023965347 | L6: 4 | M6: =L6/12 -> 0.33333333 | N6: =0.04-0.015*EXP(-M6/10) -> 0.025491758 | O6: =EXP(-N6*M6) -> 0.99153875 | P6: =O6*EXP(-inputs!$B$27*L6/12) -> 0.98988756 | Q6: =0.045-0.015*EXP(-M6/10) -> 0.030491758 | R6: =EXP(-Q6*M6) -> 0.98988756 | S6: =R6*EXP(-inputs!$B$27*L6/12) -> 0.98823912 | T6: =INDEX(P_rec,MATCH(inputs!$B$13+L6,curve_t,0))/INDEX(P_rec,MATCH(inputs!$B$13,curve_t,0)) -> 0.98899194 | U6: =T6/T5 -> 0.99721055 | V6: =T5/T6-1 -> 0.0027972556 | X6: -20 | Y6: =IF(X6<=0,100*1.04^(X6/12),100*1.025^(X6/12)) -> 93.672282 | AA6: -22 | AB6: =IF(AA6<=-13,100*1.04^((AA6+12)/12),100.1*1.032^((AA6+12)/12)) -> 96.784442 | AC6: =AB6 -> 96.784442 | AD6: =AB6 -> 96.784442 | AF6: 22 | AG6: =IF($AF6<=85,1,IF($AF6<110,(110-$AF6)/25,0)) -> 1 | AH6: =1 -> 1 | AI6: =AH6*(1-$AG6*(0.01+0.01*AI$3)) -> 0.98 | AJ6: =AI6*(1-$AG6*(0.01+0.01*AJ$3)) -> 0.96047105 | AK6: =AJ6*(1-$AG6*(0.01+0.01*AK$3)) -> 0.94153056 | AL6: =AK6*(1-$AG6*(0.01+0.01*AL$3)) -> 0.92327193 | AM6: =AL6*(1-$AG6*(0.01+0.01*AM$3)) -> 0.90576669 | AN6: =AM6*(1-$AG6*(0.01+0.01*AN$3)) -> 0.88906662 | AO6: =AN6*(1-$AG6*(0.01+0.01*AO$3)) -> 0.87320567 | AP6: =AO6*(1-$AG6*(0.01+0.01*AP$3)) -> 0.85820182 | ... FC6: =FB6*(1-$AG6*(0.01+0.01*FC$3)) -> 0.25595353
A7: valuation_date V | B7: 46387 | C7: the last day of a calendar month | F7: 25 | G7: =1-EXP(-inputs!$B$35-inputs!$B$36*inputs!$B$37^$F7*(inputs!$B$37-1)/LN(inputs!$B$37)) -> 0.00027319212 | H7: =1-EXP(-inputs!$B$35-inputs!$B$36*inputs!$B$37^($F7-4)*(inputs!$B$37-1)/LN(inputs!$B$37)) -> 0.00025331721 | I7: =0.96*G7 -> 0.00026226444 | J7: =0.96*H7 -> 0.00024318452 | L7: 5 | M7: =L7/12 -> 0.41666667 | N7: =0.04-0.015*EXP(-M7/10) -> 0.025612158 | O7: =EXP(-N7*M7) -> 0.98938501 | P7: =O7*EXP(-inputs!$B$27*L7/12) -> 0.98732594 | Q7: =0.045-0.015*EXP(-M7/10) -> 0.030612158 | R7: =EXP(-Q7*M7) -> 0.98732594 | S7: =R7*EXP(-inputs!$B$27*L7/12) -> 0.98527115 | T7: =INDEX(P_rec,MATCH(inputs!$B$13+L7,curve_t,0))/INDEX(P_rec,MATCH(inputs!$B$13,curve_t,0)) -> 0.98621641 | U7: =T7/T6 -> 0.99719358 | V7: =T6/T7-1 -> 0.0028143208 | X7: -19 | Y7: =IF(X7<=0,100*1.04^(X7/12),100*1.025^(X7/12)) -> 93.978941 | AA7: -21 | AB7: =IF(AA7<=-13,100*1.04^((AA7+12)/12),100.1*1.032^((AA7+12)/12)) -> 97.101289 | AC7: =AB7 -> 97.101289 | AD7: =AB7 -> 97.101289 | AF7: 23 | AG7: =IF($AF7<=85,1,IF($AF7<110,(110-$AF7)/25,0)) -> 1 | AH7: =1 -> 1 | AI7: =AH7*(1-$AG7*(0.01+0.01*AI$3)) -> 0.98 | AJ7: =AI7*(1-$AG7*(0.01+0.01*AJ$3)) -> 0.96047105 | AK7: =AJ7*(1-$AG7*(0.01+0.01*AK$3)) -> 0.94153056 | AL7: =AK7*(1-$AG7*(0.01+0.01*AL$3)) -> 0.92327193 | AM7: =AL7*(1-$AG7*(0.01+0.01*AM$3)) -> 0.90576669 | AN7: =AM7*(1-$AG7*(0.01+0.01*AN$3)) -> 0.88906662 | AO7: =AN7*(1-$AG7*(0.01+0.01*AO$3)) -> 0.87320567 | AP7: =AO7*(1-$AG7*(0.01+0.01*AP$3)) -> 0.85820182 | ... FC7: =FB7*(1-$AG7*(0.01+0.01*FC$3)) -> 0.25595353
A8: recognition_date V_rec | B8: 46022 | C8: a month-end | F8: 26 | G8: =1-EXP(-inputs!$B$35-inputs!$B$36*inputs!$B$37^$F8*(inputs!$B$37-1)/LN(inputs!$B$37)) -> 0.00027979075 | H8: =1-EXP(-inputs!$B$35-inputs!$B$36*inputs!$B$37^($F8-4)*(inputs!$B$37-1)/LN(inputs!$B$37)) -> 0.00025745146 | I8: =0.96*G8 -> 0.00026859912 | J8: =0.96*H8 -> 0.00024715341 | L8: 6 | M8: =L8/12 -> 0.5 | N8: =0.04-0.015*EXP(-M8/10) -> 0.025731559 | O8: =EXP(-N8*M8) -> 0.98721663 | P8: =O8*EXP(-inputs!$B$27*L8/12) -> 0.98475167 | Q8: =0.045-0.015*EXP(-M8/10) -> 0.030731559 | R8: =EXP(-Q8*M8) -> 0.98475167 | S8: =R8*EXP(-inputs!$B$27*L8/12) -> 0.98229287 | T8: =INDEX(P_rec,MATCH(inputs!$B$13+L8,curve_t,0))/INDEX(P_rec,MATCH(inputs!$B$13,curve_t,0)) -> 0.98343215 | U8: =T8/T7 -> 0.99717682 | V8: =T7/T8-1 -> 0.0028311691 | X8: -18 | Y8: =IF(X8<=0,100*1.04^(X8/12),100*1.025^(X8/12)) -> 94.286603 | AA8: -20 | AB8: =IF(AA8<=-13,100*1.04^((AA8+12)/12),100.1*1.032^((AA8+12)/12)) -> 97.419173 | AC8: =AB8 -> 97.419173 | AD8: =AB8 -> 97.419173 | AF8: 24 | AG8: =IF($AF8<=85,1,IF($AF8<110,(110-$AF8)/25,0)) -> 1 | AH8: =1 -> 1 | AI8: =AH8*(1-$AG8*(0.01+0.01*AI$3)) -> 0.98 | AJ8: =AI8*(1-$AG8*(0.01+0.01*AJ$3)) -> 0.96047105 | AK8: =AJ8*(1-$AG8*(0.01+0.01*AK$3)) -> 0.94153056 | AL8: =AK8*(1-$AG8*(0.01+0.01*AL$3)) -> 0.92327193 | AM8: =AL8*(1-$AG8*(0.01+0.01*AM$3)) -> 0.90576669 | AN8: =AM8*(1-$AG8*(0.01+0.01*AN$3)) -> 0.88906662 | AO8: =AN8*(1-$AG8*(0.01+0.01*AO$3)) -> 0.87320567 | AP8: =AO8*(1-$AG8*(0.01+0.01*AP$3)) -> 0.85820182 | ... FC8: =FB8*(1-$AG8*(0.01+0.01*FC$3)) -> 0.25595353
A9: prev_valuation_date V_prev | B9: 46022 | C9: a month-end; here equal to V_rec (C1) | F9: 27 | G9: =1-EXP(-inputs!$B$35-inputs!$B$36*inputs!$B$37^$F9*(inputs!$B$37-1)/LN(inputs!$B$37)) -> 0.00028720755 | H9: =1-EXP(-inputs!$B$35-inputs!$B$36*inputs!$B$37^($F9-4)*(inputs!$B$37-1)/LN(inputs!$B$37)) -> 0.00026209835 | I9: =0.96*G9 -> 0.00027571925 | J9: =0.96*H9 -> 0.00025161441 | L9: 7 | M9: =L9/12 -> 0.58333333 | N9: =0.04-0.015*EXP(-M9/10) -> 0.025849968 | O9: =EXP(-N9*M9) -> 0.98503397 | P9: =O9*EXP(-inputs!$B$27*L9/12) -> 0.98216514 | Q9: =0.045-0.015*EXP(-M9/10) -> 0.030849968 | R9: =EXP(-Q9*M9) -> 0.98216514 | S9: =R9*EXP(-inputs!$B$27*L9/12) -> 0.97930467 | T9: =INDEX(P_rec,MATCH(inputs!$B$13+L9,curve_t,0))/INDEX(P_rec,MATCH(inputs!$B$13,curve_t,0)) -> 0.98063948 | U9: =T9/T8 -> 0.99716028 | V9: =T8/T9-1 -> 0.002847803 | X9: -17 | Y9: =IF(X9<=0,100*1.04^(X9/12),100*1.025^(X9/12)) -> 94.595273 | AA9: -19 | AB9: =IF(AA9<=-13,100*1.04^((AA9+12)/12),100.1*1.032^((AA9+12)/12)) -> 97.738098 | AC9: =AB9 -> 97.738098 | AD9: =AB9 -> 97.738098 | AF9: 25 | AG9: =IF($AF9<=85,1,IF($AF9<110,(110-$AF9)/25,0)) -> 1 | AH9: =1 -> 1 | AI9: =AH9*(1-$AG9*(0.01+0.01*AI$3)) -> 0.98 | AJ9: =AI9*(1-$AG9*(0.01+0.01*AJ$3)) -> 0.96047105 | AK9: =AJ9*(1-$AG9*(0.01+0.01*AK$3)) -> 0.94153056 | AL9: =AK9*(1-$AG9*(0.01+0.01*AL$3)) -> 0.92327193 | AM9: =AL9*(1-$AG9*(0.01+0.01*AM$3)) -> 0.90576669 | AN9: =AM9*(1-$AG9*(0.01+0.01*AN$3)) -> 0.88906662 | AO9: =AN9*(1-$AG9*(0.01+0.01*AO$3)) -> 0.87320567 | AP9: =AO9*(1-$AG9*(0.01+0.01*AP$3)) -> 0.85820182 | ... FC9: =FB9*(1-$AG9*(0.01+0.01*FC$3)) -> 0.25595353
A10: m_V = mi(V) | B10: =12*YEAR(inputs!$B$7)+MONTH(inputs!$B$7)-1 -> 24323 | C10: mi(d) = 12 * year(d) + month(d) - 1 | F10: 28 | G10: =1-EXP(-inputs!$B$35-inputs!$B$36*inputs!$B$37^$F10*(inputs!$B$37-1)/LN(inputs!$B$37)) -> 0.00029554397 | H10: =1-EXP(-inputs!$B$35-inputs!$B$36*inputs!$B$37^($F10-4)*(inputs!$B$37-1)/LN(inputs!$B$37)) -> 0.00026732142 | I10: =0.96*G10 -> 0.00028372221 | J10: =0.96*H10 -> 0.00025662856 | L10: 8 | M10: =L10/12 -> 0.66666667 | N10: =0.04-0.015*EXP(-M10/10) -> 0.025967395 | O10: =EXP(-N10*M10) -> 0.98283739 | P10: =O10*EXP(-inputs!$B$27*L10/12) -> 0.97956672 | Q10: =0.045-0.015*EXP(-M10/10) -> 0.030967395 | R10: =EXP(-Q10*M10) -> 0.97956672 | S10: =R10*EXP(-inputs!$B$27*L10/12) -> 0.97630693 | T10: =INDEX(P_rec,MATCH(inputs!$B$13+L10,curve_t,0))/INDEX(P_rec,MATCH(inputs!$B$13,curve_t,0)) -> 0.97783873 | U10: =T10/T9 -> 0.99714396 | V10: =T9/T10-1 -> 0.0028642248 | X10: -16 | Y10: =IF(X10<=0,100*1.04^(X10/12),100*1.025^(X10/12)) -> 94.904954 | AA10: -18 | AB10: =IF(AA10<=-13,100*1.04^((AA10+12)/12),100.1*1.032^((AA10+12)/12)) -> 98.058068 | AC10: =AB10 -> 98.058068 | AD10: =AB10 -> 98.058068 | AF10: 26 | AG10: =IF($AF10<=85,1,IF($AF10<110,(110-$AF10)/25,0)) -> 1 | AH10: =1 -> 1 | AI10: =AH10*(1-$AG10*(0.01+0.01*AI$3)) -> 0.98 | AJ10: =AI10*(1-$AG10*(0.01+0.01*AJ$3)) -> 0.96047105 | AK10: =AJ10*(1-$AG10*(0.01+0.01*AK$3)) -> 0.94153056 | AL10: =AK10*(1-$AG10*(0.01+0.01*AL$3)) -> 0.92327193 | AM10: =AL10*(1-$AG10*(0.01+0.01*AM$3)) -> 0.90576669 | AN10: =AM10*(1-$AG10*(0.01+0.01*AN$3)) -> 0.88906662 | AO10: =AN10*(1-$AG10*(0.01+0.01*AO$3)) -> 0.87320567 | AP10: =AO10*(1-$AG10*(0.01+0.01*AP$3)) -> 0.85820182 | ... FC10: =FB10*(1-$AG10*(0.01+0.01*FC$3)) -> 0.25595353
A11: m_rec = mi(V_rec) | B11: =12*YEAR(inputs!$B$8)+MONTH(inputs!$B$8)-1 -> 24311 | F11: 29 | G11: =1-EXP(-inputs!$B$35-inputs!$B$36*inputs!$B$37^$F11*(inputs!$B$37-1)/LN(inputs!$B$37)) -> 0.00030491403 | H11: =1-EXP(-inputs!$B$35-inputs!$B$36*inputs!$B$37^($F11-4)*(inputs!$B$37-1)/LN(inputs!$B$37)) -> 0.00027319212 | I11: =0.96*G11 -> 0.00029271747 | J11: =0.96*H11 -> 0.00026226444 | L11: 9 | M11: =L11/12 -> 0.75 | N11: =0.04-0.015*EXP(-M11/10) -> 0.026083848 | O11: =EXP(-N11*M11) -> 0.98062723 | P11: =O11*EXP(-inputs!$B$27*L11/12) -> 0.97695676 | Q11: =0.045-0.015*EXP(-M11/10) -> 0.031083848 | R11: =EXP(-Q11*M11) -> 0.97695676 | S11: =R11*EXP(-inputs!$B$27*L11/12) -> 0.97330003 | T11: =INDEX(P_rec,MATCH(inputs!$B$13+L11,curve_t,0))/INDEX(P_rec,MATCH(inputs!$B$13,curve_t,0)) -> 0.97503022 | U11: =T11/T10 -> 0.99712784 | V11: =T10/T11-1 -> 0.0028804368 | X11: -15 | Y11: =IF(X11<=0,100*1.04^(X11/12),100*1.025^(X11/12)) -> 95.215648 | AA11: -17 | AB11: =IF(AA11<=-13,100*1.04^((AA11+12)/12),100.1*1.032^((AA11+12)/12)) -> 98.379084 | AC11: =AB11 -> 98.379084 | AD11: =AB11 -> 98.379084 | AF11: 27 | AG11: =IF($AF11<=85,1,IF($AF11<110,(110-$AF11)/25,0)) -> 1 | AH11: =1 -> 1 | AI11: =AH11*(1-$AG11*(0.01+0.01*AI$3)) -> 0.98 | AJ11: =AI11*(1-$AG11*(0.01+0.01*AJ$3)) -> 0.96047105 | AK11: =AJ11*(1-$AG11*(0.01+0.01*AK$3)) -> 0.94153056 | AL11: =AK11*(1-$AG11*(0.01+0.01*AL$3)) -> 0.92327193 | AM11: =AL11*(1-$AG11*(0.01+0.01*AM$3)) -> 0.90576669 | AN11: =AM11*(1-$AG11*(0.01+0.01*AN$3)) -> 0.88906662 | AO11: =AN11*(1-$AG11*(0.01+0.01*AO$3)) -> 0.87320567 | AP11: =AO11*(1-$AG11*(0.01+0.01*AP$3)) -> 0.85820182 | ... FC11: =FB11*(1-$AG11*(0.01+0.01*FC$3)) -> 0.25595353
A12: m_prev = mi(V_prev) | B12: =12*YEAR(inputs!$B$9)+MONTH(inputs!$B$9)-1 -> 24311 | F12: 30 | G12: =1-EXP(-inputs!$B$35-inputs!$B$36*inputs!$B$37^$F12*(inputs!$B$37-1)/LN(inputs!$B$37)) -> 0.00031544586 | H12: =1-EXP(-inputs!$B$35-inputs!$B$36*inputs!$B$37^($F12-4)*(inputs!$B$37-1)/LN(inputs!$B$37)) -> 0.00027979075 | I12: =0.96*G12 -> 0.00030282803 | J12: =0.96*H12 -> 0.00026859912 | L12: 10 | M12: =L12/12 -> 0.83333333 | N12: =0.04-0.015*EXP(-M12/10) -> 0.026199334 | O12: =EXP(-N12*M12) -> 0.97840383 | P12: =O12*EXP(-inputs!$B$27*L12/12) -> 0.97433563 | Q12: =0.045-0.015*EXP(-M12/10) -> 0.031199334 | R12: =EXP(-Q12*M12) -> 0.97433563 | S12: =R12*EXP(-inputs!$B$27*L12/12) -> 0.97028434 | T12: =INDEX(P_rec,MATCH(inputs!$B$13+L12,curve_t,0))/INDEX(P_rec,MATCH(inputs!$B$13,curve_t,0)) -> 0.97221426 | U12: =T12/T11 -> 0.99711192 | V12: =T11/T12-1 -> 0.0028964416 | X12: -14 | Y12: =IF(X12<=0,100*1.04^(X12/12),100*1.025^(X12/12)) -> 95.527359 | AA12: -16 | AB12: =IF(AA12<=-13,100*1.04^((AA12+12)/12),100.1*1.032^((AA12+12)/12)) -> 98.701152 | AC12: =AB12 -> 98.701152 | AD12: =AB12 -> 98.701152 | AF12: 28 | AG12: =IF($AF12<=85,1,IF($AF12<110,(110-$AF12)/25,0)) -> 1 | AH12: =1 -> 1 | AI12: =AH12*(1-$AG12*(0.01+0.01*AI$3)) -> 0.98 | AJ12: =AI12*(1-$AG12*(0.01+0.01*AJ$3)) -> 0.96047105 | AK12: =AJ12*(1-$AG12*(0.01+0.01*AK$3)) -> 0.94153056 | AL12: =AK12*(1-$AG12*(0.01+0.01*AL$3)) -> 0.92327193 | AM12: =AL12*(1-$AG12*(0.01+0.01*AM$3)) -> 0.90576669 | AN12: =AM12*(1-$AG12*(0.01+0.01*AN$3)) -> 0.88906662 | AO12: =AN12*(1-$AG12*(0.01+0.01*AO$3)) -> 0.87320567 | AP12: =AO12*(1-$AG12*(0.01+0.01*AP$3)) -> 0.85820182 | ... FC12: =FB12*(1-$AG12*(0.01+0.01*FC$3)) -> 0.25595353
A13: tau0 = m_V - m_rec | B13: =inputs!$B$10-inputs!$B$11 -> 12 | C13: months from recognition to V | F13: 31 | G13: =1-EXP(-inputs!$B$35-inputs!$B$36*inputs!$B$37^$F13*(inputs!$B$37-1)/LN(inputs!$B$37)) -> 0.00032728352 | H13: =1-EXP(-inputs!$B$35-inputs!$B$36*inputs!$B$37^($F13-4)*(inputs!$B$37-1)/LN(inputs!$B$37)) -> 0.00028720755 | I13: =0.96*G13 -> 0.00031419218 | J13: =0.96*H13 -> 0.00027571925 | L13: 11 | M13: =L13/12 -> 0.91666667 | N13: =0.04-0.015*EXP(-M13/10) -> 0.026313861 | O13: =EXP(-N13*M13) -> 0.97616755 | P13: =O13*EXP(-inputs!$B$27*L13/12) -> 0.97170368 | Q13: =0.045-0.015*EXP(-M13/10) -> 0.031313861 | R13: =EXP(-Q13*M13) -> 0.97170368 | S13: =R13*EXP(-inputs!$B$27*L13/12) -> 0.96726023 | T13: =INDEX(P_rec,MATCH(inputs!$B$13+L13,curve_t,0))/INDEX(P_rec,MATCH(inputs!$B$13,curve_t,0)) -> 0.96939116 | U13: =T13/T12 -> 0.99709622 | V13: =T12/T13-1 -> 0.0029122412 | X13: -13 | Y13: =IF(X13<=0,100*1.04^(X13/12),100*1.025^(X13/12)) -> 95.840091 | AA13: -15 | AB13: =IF(AA13<=-13,100*1.04^((AA13+12)/12),100.1*1.032^((AA13+12)/12)) -> 99.024274 | AC13: =AB13 -> 99.024274 | AD13: =AB13 -> 99.024274 | AF13: 29 | AG13: =IF($AF13<=85,1,IF($AF13<110,(110-$AF13)/25,0)) -> 1 | AH13: =1 -> 1 | AI13: =AH13*(1-$AG13*(0.01+0.01*AI$3)) -> 0.98 | AJ13: =AI13*(1-$AG13*(0.01+0.01*AJ$3)) -> 0.96047105 | AK13: =AJ13*(1-$AG13*(0.01+0.01*AK$3)) -> 0.94153056 | AL13: =AK13*(1-$AG13*(0.01+0.01*AL$3)) -> 0.92327193 | AM13: =AL13*(1-$AG13*(0.01+0.01*AM$3)) -> 0.90576669 | AN13: =AM13*(1-$AG13*(0.01+0.01*AN$3)) -> 0.88906662 | AO13: =AN13*(1-$AG13*(0.01+0.01*AO$3)) -> 0.87320567 | AP13: =AO13*(1-$AG13*(0.01+0.01*AP$3)) -> 0.85820182 | ... FC13: =FB13*(1-$AG13*(0.01+0.01*FC$3)) -> 0.25595353
A14: tau = m_V - m_prev | B14: =inputs!$B$10-inputs!$B$12 -> 12 | C14: the reporting period in months | F14: 32 | G14: =1-EXP(-inputs!$B$35-inputs!$B$36*inputs!$B$37^$F14*(inputs!$B$37-1)/LN(inputs!$B$37)) -> 0.00034058887 | H14: =1-EXP(-inputs!$B$35-inputs!$B$36*inputs!$B$37^($F14-4)*(inputs!$B$37-1)/LN(inputs!$B$37)) -> 0.00029554397 | I14: =0.96*G14 -> 0.00032696532 | J14: =0.96*H14 -> 0.00028372221 | L14: 12 | M14: =L14/12 -> 1 | N14: =0.04-0.015*EXP(-M14/10) -> 0.026427439 | O14: =EXP(-N14*M14) -> 0.97391871 | P14: =O14*EXP(-inputs!$B$27*L14/12) -> 0.96906127 | Q14: =0.045-0.015*EXP(-M14/10) -> 0.031427439 | R14: =EXP(-Q14*M14) -> 0.96906127 | S14: =R14*EXP(-inputs!$B$27*L14/12) -> 0.96422806 | T14: =INDEX(P_rec,MATCH(inputs!$B$13+L14,curve_t,0))/INDEX(P_rec,MATCH(inputs!$B$13,curve_t,0)) -> 0.96656122 | U14: =T14/T13 -> 0.99708071 | V14: =T13/T14-1 -> 0.0029278382 | X14: -12 | Y14: =IF(X14<=0,100*1.04^(X14/12),100*1.025^(X14/12)) -> 96.153846 | AA14: -14 | AB14: =IF(AA14<=-13,100*1.04^((AA14+12)/12),100.1*1.032^((AA14+12)/12)) -> 99.348453 | AC14: =AB14 -> 99.348453 | AD14: =AB14 -> 99.348453 | AF14: 30 | AG14: =IF($AF14<=85,1,IF($AF14<110,(110-$AF14)/25,0)) -> 1 | AH14: =1 -> 1 | AI14: =AH14*(1-$AG14*(0.01+0.01*AI$3)) -> 0.98 | AJ14: =AI14*(1-$AG14*(0.01+0.01*AJ$3)) -> 0.96047105 | AK14: =AJ14*(1-$AG14*(0.01+0.01*AK$3)) -> 0.94153056 | AL14: =AK14*(1-$AG14*(0.01+0.01*AL$3)) -> 0.92327193 | AM14: =AL14*(1-$AG14*(0.01+0.01*AM$3)) -> 0.90576669 | AN14: =AM14*(1-$AG14*(0.01+0.01*AN$3)) -> 0.88906662 | AO14: =AN14*(1-$AG14*(0.01+0.01*AO$3)) -> 0.87320567 | AP14: =AO14*(1-$AG14*(0.01+0.01*AP$3)) -> 0.85820182 | ... FC14: =FB14*(1-$AG14*(0.01+0.01*FC$3)) -> 0.25595353
A15: cpi_lag_m L | B15: 3 | C15: build-time constant of the CPI class | F15: 33 | G15: =1-EXP(-inputs!$B$35-inputs!$B$36*inputs!$B$37^$F15*(inputs!$B$37-1)/LN(inputs!$B$37)) -> 0.00035554388 | H15: =1-EXP(-inputs!$B$35-inputs!$B$36*inputs!$B$37^($F15-4)*(inputs!$B$37-1)/LN(inputs!$B$37)) -> 0.00030491403 | I15: =0.96*G15 -> 0.00034132212 | J15: =0.96*H15 -> 0.00029271747 | L15: 13 | M15: =L15/12 -> 1.0833333 | N15: =0.04-0.015*EXP(-M15/10) -> 0.026540073 | O15: =EXP(-N15*M15) -> 0.97165765 | P15: =O15*EXP(-inputs!$B$27*L15/12) -> 0.96640874 | Q15: =0.045-0.015*EXP(-M15/10) -> 0.031540073 | R15: =EXP(-Q15*M15) -> 0.96640874 | S15: =R15*EXP(-inputs!$B$27*L15/12) -> 0.96118817 | T15: =INDEX(P_rec,MATCH(inputs!$B$13+L15,curve_t,0))/INDEX(P_rec,MATCH(inputs!$B$13,curve_t,0)) -> 0.96372475 | U15: =T15/T14 -> 0.9970654 | V15: =T14/T15-1 -> 0.0029432346 | X15: -11 | Y15: =IF(X15<=0,100*1.04^(X15/12),100*1.025^(X15/12)) -> 96.468629 | AA15: -13 | AB15: =IF(AA15<=-13,100*1.04^((AA15+12)/12),100.1*1.032^((AA15+12)/12)) -> 99.673694 | AC15: =AB15 -> 99.673694 | AD15: =AB15 -> 99.673694 | AF15: 31 | AG15: =IF($AF15<=85,1,IF($AF15<110,(110-$AF15)/25,0)) -> 1 | AH15: =1 -> 1 | AI15: =AH15*(1-$AG15*(0.01+0.01*AI$3)) -> 0.98 | AJ15: =AI15*(1-$AG15*(0.01+0.01*AJ$3)) -> 0.96047105 | AK15: =AJ15*(1-$AG15*(0.01+0.01*AK$3)) -> 0.94153056 | AL15: =AK15*(1-$AG15*(0.01+0.01*AL$3)) -> 0.92327193 | AM15: =AL15*(1-$AG15*(0.01+0.01*AM$3)) -> 0.90576669 | AN15: =AM15*(1-$AG15*(0.01+0.01*AN$3)) -> 0.88906662 | AO15: =AN15*(1-$AG15*(0.01+0.01*AO$3)) -> 0.87320567 | AP15: =AO15*(1-$AG15*(0.01+0.01*AP$3)) -> 0.85820182 | ... FC15: =FB15*(1-$AG15*(0.01+0.01*FC$3)) -> 0.25595353
A16: include_inv_exp | B16: TRUE | F16: 34 | G16: =1-EXP(-inputs!$B$35-inputs!$B$36*inputs!$B$37^$F16*(inputs!$B$37-1)/LN(inputs!$B$37)) -> 0.00037235304 | H16: =1-EXP(-inputs!$B$35-inputs!$B$36*inputs!$B$37^($F16-4)*(inputs!$B$37-1)/LN(inputs!$B$37)) -> 0.00031544586 | I16: =0.96*G16 -> 0.00035745892 | J16: =0.96*H16 -> 0.00030282803 | L16: 14 | M16: =L16/12 -> 1.1666667 | N16: =0.04-0.015*EXP(-M16/10) -> 0.026651773 | O16: =EXP(-N16*M16) -> 0.9693847 | P16: =O16*EXP(-inputs!$B$27*L16/12) -> 0.96374642 | Q16: =0.045-0.015*EXP(-M16/10) -> 0.031651773 | R16: =EXP(-Q16*M16) -> 0.96374642 | S16: =R16*EXP(-inputs!$B$27*L16/12) -> 0.95814093 | T16: =INDEX(P_rec,MATCH(inputs!$B$13+L16,curve_t,0))/INDEX(P_rec,MATCH(inputs!$B$13,curve_t,0)) -> 0.96088205 | U16: =T16/T15 -> 0.99705029 | V16: =T15/T16-1 -> 0.0029584328 | X16: -10 | Y16: =IF(X16<=0,100*1.04^(X16/12),100*1.025^(X16/12)) -> 96.784442 | AA16: -12 | AB16: =IF(AA16<=-13,100*1.04^((AA16+12)/12),100.1*1.032^((AA16+12)/12)) -> 100.1 | AC16: =AB16 -> 100.1 | AD16: =AB16 -> 100.1 | AF16: 32 | AG16: =IF($AF16<=85,1,IF($AF16<110,(110-$AF16)/25,0)) -> 1 | AH16: =1 -> 1 | AI16: =AH16*(1-$AG16*(0.01+0.01*AI$3)) -> 0.98 | AJ16: =AI16*(1-$AG16*(0.01+0.01*AJ$3)) -> 0.96047105 | AK16: =AJ16*(1-$AG16*(0.01+0.01*AK$3)) -> 0.94153056 | AL16: =AK16*(1-$AG16*(0.01+0.01*AL$3)) -> 0.92327193 | AM16: =AL16*(1-$AG16*(0.01+0.01*AM$3)) -> 0.90576669 | AN16: =AM16*(1-$AG16*(0.01+0.01*AN$3)) -> 0.88906662 | AO16: =AN16*(1-$AG16*(0.01+0.01*AO$3)) -> 0.87320567 | AP16: =AO16*(1-$AG16*(0.01+0.01*AP$3)) -> 0.85820182 | ... FC16: =FB16*(1-$AG16*(0.01+0.01*FC$3)) -> 0.25595353
A17: discount_coverage_units | B17: TRUE | C17: the only form in the spec (C13) | F17: 35 | G17: =1-EXP(-inputs!$B$35-inputs!$B$36*inputs!$B$37^$F17*(inputs!$B$37-1)/LN(inputs!$B$37)) -> 0.0003912462 | H17: =1-EXP(-inputs!$B$35-inputs!$B$36*inputs!$B$37^($F17-4)*(inputs!$B$37-1)/LN(inputs!$B$37)) -> 0.00032728352 | I17: =0.96*G17 -> 0.00037559635 | J17: =0.96*H17 -> 0.00031419218 | L17: 15 | M17: =L17/12 -> 1.25 | N17: =0.04-0.015*EXP(-M17/10) -> 0.026762546 | O17: =EXP(-N17*M17) -> 0.96710019 | P17: =O17*EXP(-inputs!$B$27*L17/12) -> 0.96107466 | Q17: =0.045-0.015*EXP(-M17/10) -> 0.031762546 | R17: =EXP(-Q17*M17) -> 0.96107466 | S17: =R17*EXP(-inputs!$B$27*L17/12) -> 0.95508668 | T17: =INDEX(P_rec,MATCH(inputs!$B$13+L17,curve_t,0))/INDEX(P_rec,MATCH(inputs!$B$13,curve_t,0)) -> 0.9580334 | U17: =T17/T16 -> 0.99703538 | V17: =T16/T17-1 -> 0.0029734351 | X17: -9 | Y17: =IF(X17<=0,100*1.04^(X17/12),100*1.025^(X17/12)) -> 97.101289 | AA17: -11 | AB17: =IF(AA17<=-13,100*1.04^((AA17+12)/12),100.1*1.032^((AA17+12)/12)) -> 100.3631 | AC17: =AB17 -> 100.3631 | AD17: =AB17 -> 100.3631 | AF17: 33 | AG17: =IF($AF17<=85,1,IF($AF17<110,(110-$AF17)/25,0)) -> 1 | AH17: =1 -> 1 | AI17: =AH17*(1-$AG17*(0.01+0.01*AI$3)) -> 0.98 | AJ17: =AI17*(1-$AG17*(0.01+0.01*AJ$3)) -> 0.96047105 | AK17: =AJ17*(1-$AG17*(0.01+0.01*AK$3)) -> 0.94153056 | AL17: =AK17*(1-$AG17*(0.01+0.01*AL$3)) -> 0.92327193 | AM17: =AL17*(1-$AG17*(0.01+0.01*AM$3)) -> 0.90576669 | AN17: =AM17*(1-$AG17*(0.01+0.01*AN$3)) -> 0.88906662 | AO17: =AN17*(1-$AG17*(0.01+0.01*AO$3)) -> 0.87320567 | AP17: =AO17*(1-$AG17*(0.01+0.01*AP$3)) -> 0.85820182 | ... FC17: =FB17*(1-$AG17*(0.01+0.01*FC$3)) -> 0.25595353
A18: scenario count J | B18: 1 | C18: one scenario per run (G6) | F18: 36 | G18: =1-EXP(-inputs!$B$35-inputs!$B$36*inputs!$B$37^$F18*(inputs!$B$37-1)/LN(inputs!$B$37)) -> 0.00041248168 | H18: =1-EXP(-inputs!$B$35-inputs!$B$36*inputs!$B$37^($F18-4)*(inputs!$B$37-1)/LN(inputs!$B$37)) -> 0.00034058887 | I18: =0.96*G18 -> 0.00039598241 | J18: =0.96*H18 -> 0.00032696532 | L18: 16 | M18: =L18/12 -> 1.3333333 | N18: =0.04-0.015*EXP(-M18/10) -> 0.0268724 | O18: =EXP(-N18*M18) -> 0.96480442 | P18: =O18*EXP(-inputs!$B$27*L18/12) -> 0.95839379 | Q18: =0.045-0.015*EXP(-M18/10) -> 0.0318724 | R18: =EXP(-Q18*M18) -> 0.95839379 | S18: =R18*EXP(-inputs!$B$27*L18/12) -> 0.95202575 | T18: =INDEX(P_rec,MATCH(inputs!$B$13+L18,curve_t,0))/INDEX(P_rec,MATCH(inputs!$B$13,curve_t,0)) -> 0.95517909 | U18: =T18/T17 -> 0.99702066 | V18: =T17/T18-1 -> 0.0029882435 | X18: -8 | Y18: =IF(X18<=0,100*1.04^(X18/12),100*1.025^(X18/12)) -> 97.419173 | AA18: -10 | AB18: =IF(AA18<=-13,100*1.04^((AA18+12)/12),100.1*1.032^((AA18+12)/12)) -> 100.62688 | AC18: =AB18 -> 100.62688 | AD18: =AB18 -> 100.62688 | AF18: 34 | AG18: =IF($AF18<=85,1,IF($AF18<110,(110-$AF18)/25,0)) -> 1 | AH18: =1 -> 1 | AI18: =AH18*(1-$AG18*(0.01+0.01*AI$3)) -> 0.98 | AJ18: =AI18*(1-$AG18*(0.01+0.01*AJ$3)) -> 0.96047105 | AK18: =AJ18*(1-$AG18*(0.01+0.01*AK$3)) -> 0.94153056 | AL18: =AK18*(1-$AG18*(0.01+0.01*AL$3)) -> 0.92327193 | AM18: =AL18*(1-$AG18*(0.01+0.01*AM$3)) -> 0.90576669 | AN18: =AM18*(1-$AG18*(0.01+0.01*AN$3)) -> 0.88906662 | AO18: =AN18*(1-$AG18*(0.01+0.01*AO$3)) -> 0.87320567 | AP18: =AO18*(1-$AG18*(0.01+0.01*AP$3)) -> 0.85820182 | ... FC18: =FB18*(1-$AG18*(0.01+0.01*FC$3)) -> 0.25595353
A19: T (recognition run) = 12*120 + 1 - min a0 at V_rec | B19: =12*120+1-MIN(inputs!$B$68,inputs!$C$68) -> 501 | C19: the generator writes rows t = 0 .. 501 on the REC sheets | F19: 37 | G19: =1-EXP(-inputs!$B$35-inputs!$B$36*inputs!$B$37^$F19*(inputs!$B$37-1)/LN(inputs!$B$37)) -> 0.00043634983 | H19: =1-EXP(-inputs!$B$35-inputs!$B$36*inputs!$B$37^($F19-4)*(inputs!$B$37-1)/LN(inputs!$B$37)) -> 0.00035554388 | I19: =0.96*G19 -> 0.00041889583 | J19: =0.96*H19 -> 0.00034132212 | L19: 17 | M19: =L19/12 -> 1.4166667 | N19: =0.04-0.015*EXP(-M19/10) -> 0.026981342 | O19: =EXP(-N19*M19) -> 0.96249773 | P19: =O19*EXP(-inputs!$B$27*L19/12) -> 0.95570413 | Q19: =0.045-0.015*EXP(-M19/10) -> 0.031981342 | R19: =EXP(-Q19*M19) -> 0.95570413 | S19: =R19*EXP(-inputs!$B$27*L19/12) -> 0.94895848 | T19: =INDEX(P_rec,MATCH(inputs!$B$13+L19,curve_t,0))/INDEX(P_rec,MATCH(inputs!$B$13,curve_t,0)) -> 0.95231941 | U19: =T19/T18 -> 0.99700613 | V19: =T18/T19-1 -> 0.0030028603 | X19: -7 | Y19: =IF(X19<=0,100*1.04^(X19/12),100*1.025^(X19/12)) -> 97.738098 | AA19: -9 | AB19: =IF(AA19<=-13,100*1.04^((AA19+12)/12),100.1*1.032^((AA19+12)/12)) -> 100.89137 | AC19: =AB19 -> 100.89137 | AD19: =AB19 -> 100.89137 | AF19: 35 | AG19: =IF($AF19<=85,1,IF($AF19<110,(110-$AF19)/25,0)) -> 1 | AH19: =1 -> 1 | AI19: =AH19*(1-$AG19*(0.01+0.01*AI$3)) -> 0.98 | AJ19: =AI19*(1-$AG19*(0.01+0.01*AJ$3)) -> 0.96047105 | AK19: =AJ19*(1-$AG19*(0.01+0.01*AK$3)) -> 0.94153056 | AL19: =AK19*(1-$AG19*(0.01+0.01*AL$3)) -> 0.92327193 | AM19: =AL19*(1-$AG19*(0.01+0.01*AM$3)) -> 0.90576669 | AN19: =AM19*(1-$AG19*(0.01+0.01*AN$3)) -> 0.88906662 | AO19: =AN19*(1-$AG19*(0.01+0.01*AO$3)) -> 0.87320567 | AP19: =AO19*(1-$AG19*(0.01+0.01*AP$3)) -> 0.85820182 | ... FC19: =FB19*(1-$AG19*(0.01+0.01*FC$3)) -> 0.25595353
A20: T (runs at V) = 12*120 + 1 - min a0 at V | B20: =12*120+1-MIN(inputs!$B$69,inputs!$C$69) -> 489 | C20: the generator writes rows t = 0 .. 489 on the OLD, NEW and CUR sheets | F20: 38 | G20: =1-EXP(-inputs!$B$35-inputs!$B$36*inputs!$B$37^$F20*(inputs!$B$37-1)/LN(inputs!$B$37)) -> 0.00046317694 | H20: =1-EXP(-inputs!$B$35-inputs!$B$36*inputs!$B$37^($F20-4)*(inputs!$B$37-1)/LN(inputs!$B$37)) -> 0.00037235304 | I20: =0.96*G20 -> 0.00044464986 | J20: =0.96*H20 -> 0.00035745892 | L20: 18 | M20: =L20/12 -> 1.5 | N20: =0.04-0.015*EXP(-M20/10) -> 0.02708938 | O20: =EXP(-N20*M20) -> 0.96018042 | P20: =O20*EXP(-inputs!$B$27*L20/12) -> 0.95300601 | Q20: =0.045-0.015*EXP(-M20/10) -> 0.03208938 | R20: =EXP(-Q20*M20) -> 0.95300601 | S20: =R20*EXP(-inputs!$B$27*L20/12) -> 0.9458852 | T20: =INDEX(P_rec,MATCH(inputs!$B$13+L20,curve_t,0))/INDEX(P_rec,MATCH(inputs!$B$13,curve_t,0)) -> 0.94945463 | U20: =T20/T19 -> 0.99699179 | V20: =T19/T20-1 -> 0.0030172876 | X20: -6 | Y20: =IF(X20<=0,100*1.04^(X20/12),100*1.025^(X20/12)) -> 98.058068 | AA20: -8 | AB20: =IF(AA20<=-13,100*1.04^((AA20+12)/12),100.1*1.032^((AA20+12)/12)) -> 101.15654 | AC20: =AB20 -> 101.15654 | AD20: =AB20 -> 101.15654 | AF20: 36 | AG20: =IF($AF20<=85,1,IF($AF20<110,(110-$AF20)/25,0)) -> 1 | AH20: =1 -> 1 | AI20: =AH20*(1-$AG20*(0.01+0.01*AI$3)) -> 0.98 | AJ20: =AI20*(1-$AG20*(0.01+0.01*AJ$3)) -> 0.96047105 | AK20: =AJ20*(1-$AG20*(0.01+0.01*AK$3)) -> 0.94153056 | AL20: =AK20*(1-$AG20*(0.01+0.01*AL$3)) -> 0.92327193 | AM20: =AL20*(1-$AG20*(0.01+0.01*AM$3)) -> 0.90576669 | AN20: =AM20*(1-$AG20*(0.01+0.01*AN$3)) -> 0.88906662 | AO20: =AN20*(1-$AG20*(0.01+0.01*AO$3)) -> 0.87320567 | AP20: =AO20*(1-$AG20*(0.01+0.01*AP$3)) -> 0.85820182 | ... FC20: =FB20*(1-$AG20*(0.01+0.01*FC$3)) -> 0.25595353
F21: 39 | G21: =1-EXP(-inputs!$B$35-inputs!$B$36*inputs!$B$37^$F21*(inputs!$B$37-1)/LN(inputs!$B$37)) -> 0.00049332976 | H21: =1-EXP(-inputs!$B$35-inputs!$B$36*inputs!$B$37^($F21-4)*(inputs!$B$37-1)/LN(inputs!$B$37)) -> 0.0003912462 | I21: =0.96*G21 -> 0.00047359657 | J21: =0.96*H21 -> 0.00037559635 | L21: 19 | M21: =L21/12 -> 1.5833333 | N21: =0.04-0.015*EXP(-M21/10) -> 0.027196522 | O21: =EXP(-N21*M21) -> 0.95785281 | P21: =O21*EXP(-inputs!$B$27*L21/12) -> 0.95029974 | Q21: =0.045-0.015*EXP(-M21/10) -> 0.032196522 | R21: =EXP(-Q21*M21) -> 0.95029974 | S21: =R21*EXP(-inputs!$B$27*L21/12) -> 0.94280624 | T21: =INDEX(P_rec,MATCH(inputs!$B$13+L21,curve_t,0))/INDEX(P_rec,MATCH(inputs!$B$13,curve_t,0)) -> 0.94658503 | U21: =T21/T20 -> 0.99697763 | V21: =T20/T21-1 -> 0.0030315276 | X21: -5 | Y21: =IF(X21<=0,100*1.04^(X21/12),100*1.025^(X21/12)) -> 98.379084 | AA21: -7 | AB21: =IF(AA21<=-13,100*1.04^((AA21+12)/12),100.1*1.032^((AA21+12)/12)) -> 101.42242 | AC21: =AB21 -> 101.42242 | AD21: =AB21 -> 101.42242 | AF21: 37 | AG21: =IF($AF21<=85,1,IF($AF21<110,(110-$AF21)/25,0)) -> 1 | AH21: =1 -> 1 | AI21: =AH21*(1-$AG21*(0.01+0.01*AI$3)) -> 0.98 | AJ21: =AI21*(1-$AG21*(0.01+0.01*AJ$3)) -> 0.96047105 | AK21: =AJ21*(1-$AG21*(0.01+0.01*AK$3)) -> 0.94153056 | AL21: =AK21*(1-$AG21*(0.01+0.01*AL$3)) -> 0.92327193 | AM21: =AL21*(1-$AG21*(0.01+0.01*AM$3)) -> 0.90576669 | AN21: =AM21*(1-$AG21*(0.01+0.01*AN$3)) -> 0.88906662 | AO21: =AN21*(1-$AG21*(0.01+0.01*AO$3)) -> 0.87320567 | AP21: =AO21*(1-$AG21*(0.01+0.01*AP$3)) -> 0.85820182 | ... FC21: =FB21*(1-$AG21*(0.01+0.01*FC$3)) -> 0.25595353
A22: 3.5 Assumption tables: scalar tables and the constants derived from them | F22: 40 | G22: =1-EXP(-inputs!$B$35-inputs!$B$36*inputs!$B$37^$F22*(inputs!$B$37-1)/LN(inputs!$B$37)) -> 0.00052722044 | H22: =1-EXP(-inputs!$B$35-inputs!$B$36*inputs!$B$37^($F22-4)*(inputs!$B$37-1)/LN(inputs!$B$37)) -> 0.00041248168 | I22: =0.96*G22 -> 0.00050613163 | J22: =0.96*H22 -> 0.00039598241 | L22: 20 | M22: =L22/12 -> 1.6666667 | N22: =0.04-0.015*EXP(-M22/10) -> 0.027302774 | O22: =EXP(-N22*M22) -> 0.95551518 | P22: =O22*EXP(-inputs!$B$27*L22/12) -> 0.94758564 | Q22: =0.045-0.015*EXP(-M22/10) -> 0.032302774 | R22: =EXP(-Q22*M22) -> 0.94758564 | S22: =R22*EXP(-inputs!$B$27*L22/12) -> 0.93972191 | T22: =INDEX(P_rec,MATCH(inputs!$B$13+L22,curve_t,0))/INDEX(P_rec,MATCH(inputs!$B$13,curve_t,0)) -> 0.94371088 | U22: =T22/T21 -> 0.99696366 | V22: =T21/T22-1 -> 0.0030455824 | X22: -4 | Y22: =IF(X22<=0,100*1.04^(X22/12),100*1.025^(X22/12)) -> 98.701152 | AA22: -6 | AB22: =IF(AA22<=-13,100*1.04^((AA22+12)/12),100.1*1.032^((AA22+12)/12)) -> 101.68899 | AC22: =AB22 -> 101.68899 | AD22: =AB22 -> 101.68899 | AF22: 38 | AG22: =IF($AF22<=85,1,IF($AF22<110,(110-$AF22)/25,0)) -> 1 | AH22: =1 -> 1 | AI22: =AH22*(1-$AG22*(0.01+0.01*AI$3)) -> 0.98 | AJ22: =AI22*(1-$AG22*(0.01+0.01*AJ$3)) -> 0.96047105 | AK22: =AJ22*(1-$AG22*(0.01+0.01*AK$3)) -> 0.94153056 | AL22: =AK22*(1-$AG22*(0.01+0.01*AL$3)) -> 0.92327193 | AM22: =AL22*(1-$AG22*(0.01+0.01*AM$3)) -> 0.90576669 | AN22: =AM22*(1-$AG22*(0.01+0.01*AN$3)) -> 0.88906662 | AO22: =AN22*(1-$AG22*(0.01+0.01*AO$3)) -> 0.87320567 | AP22: =AO22*(1-$AG22*(0.01+0.01*AP$3)) -> 0.85820182 | ... FC22: =FB22*(1-$AG22*(0.01+0.01*FC$3)) -> 0.25595353
A23: expense v1: maint_pm (December 2025 prices) | B23: 5 | C23: version 1, priced at V_prev; used by REC as is, by OLD rebased | F23: 41 | G23: =1-EXP(-inputs!$B$35-inputs!$B$36*inputs!$B$37^$F23*(inputs!$B$37-1)/LN(inputs!$B$37)) -> 0.0005653122 | H23: =1-EXP(-inputs!$B$35-inputs!$B$36*inputs!$B$37^($F23-4)*(inputs!$B$37-1)/LN(inputs!$B$37)) -> 0.00043634983 | I23: =0.96*G23 -> 0.00054269971 | J23: =0.96*H23 -> 0.00041889583 | L23: 21 | M23: =L23/12 -> 1.75 | N23: =0.04-0.015*EXP(-M23/10) -> 0.027408145 | O23: =EXP(-N23*M23) -> 0.95316786 | P23: =O23*EXP(-inputs!$B$27*L23/12) -> 0.94486402 | Q23: =0.045-0.015*EXP(-M23/10) -> 0.032408145 | R23: =EXP(-Q23*M23) -> 0.94486402 | S23: =R23*EXP(-inputs!$B$27*L23/12) -> 0.93663253 | T23: =INDEX(P_rec,MATCH(inputs!$B$13+L23,curve_t,0))/INDEX(P_rec,MATCH(inputs!$B$13,curve_t,0)) -> 0.94083245 | U23: =T23/T22 -> 0.99694988 | V23: =T22/T23-1 -> 0.0030594541 | X23: -3 | Y23: =IF(X23<=0,100*1.04^(X23/12),100*1.025^(X23/12)) -> 99.024274 | AA23: -5 | AB23: =IF(AA23<=-13,100*1.04^((AA23+12)/12),100.1*1.032^((AA23+12)/12)) -> 101.95626 | AC23: =AB23 -> 101.95626 | AD23: =AB23 -> 101.95626 | AF23: 39 | AG23: =IF($AF23<=85,1,IF($AF23<110,(110-$AF23)/25,0)) -> 1 | AH23: =1 -> 1 | AI23: =AH23*(1-$AG23*(0.01+0.01*AI$3)) -> 0.98 | AJ23: =AI23*(1-$AG23*(0.01+0.01*AJ$3)) -> 0.96047105 | AK23: =AJ23*(1-$AG23*(0.01+0.01*AK$3)) -> 0.94153056 | AL23: =AK23*(1-$AG23*(0.01+0.01*AL$3)) -> 0.92327193 | AM23: =AL23*(1-$AG23*(0.01+0.01*AM$3)) -> 0.90576669 | AN23: =AM23*(1-$AG23*(0.01+0.01*AN$3)) -> 0.88906662 | AO23: =AN23*(1-$AG23*(0.01+0.01*AO$3)) -> 0.87320567 | AP23: =AO23*(1-$AG23*(0.01+0.01*AP$3)) -> 0.85820182 | ... FC23: =FB23*(1-$AG23*(0.01+0.01*FC$3)) -> 0.25595353
A24: expense v2: maint_pm (December 2026 prices) | B24: 5.3 | C24: version 2, priced at V; used by NEW and CUR | F24: 42 | G24: =1-EXP(-inputs!$B$35-inputs!$B$36*inputs!$B$37^$F24*(inputs!$B$37-1)/LN(inputs!$B$37)) -> 0.0006081256 | H24: =1-EXP(-inputs!$B$35-inputs!$B$36*inputs!$B$37^($F24-4)*(inputs!$B$37-1)/LN(inputs!$B$37)) -> 0.00046317694 | I24: =0.96*G24 -> 0.00058380057 | J24: =0.96*H24 -> 0.00044464986 | L24: 22 | M24: =L24/12 -> 1.8333333 | N24: =0.04-0.015*EXP(-M24/10) -> 0.027512641 | O24: =EXP(-N24*M24) -> 0.95081113 | P24: =O24*EXP(-inputs!$B$27*L24/12) -> 0.94213518 | Q24: =0.045-0.015*EXP(-M24/10) -> 0.032512641 | R24: =EXP(-Q24*M24) -> 0.94213518 | S24: =R24*EXP(-inputs!$B$27*L24/12) -> 0.93353841 | T24: =INDEX(P_rec,MATCH(inputs!$B$13+L24,curve_t,0))/INDEX(P_rec,MATCH(inputs!$B$13,curve_t,0)) -> 0.93794999 | U24: =T24/T23 -> 0.99693627 | V24: =T23/T24-1 -> 0.0030731446 | X24: -2 | Y24: =IF(X24<=0,100*1.04^(X24/12),100*1.025^(X24/12)) -> 99.348453 | AA24: -4 | AB24: =IF(AA24<=-13,100*1.04^((AA24+12)/12),100.1*1.032^((AA24+12)/12)) -> 102.22424 | AC24: =AB24 -> 102.22424 | AD24: =AB24 -> 102.22424 | AF24: 40 | AG24: =IF($AF24<=85,1,IF($AF24<110,(110-$AF24)/25,0)) -> 1 | AH24: =1 -> 1 | AI24: =AH24*(1-$AG24*(0.01+0.01*AI$3)) -> 0.98 | AJ24: =AI24*(1-$AG24*(0.01+0.01*AJ$3)) -> 0.96047105 | AK24: =AJ24*(1-$AG24*(0.01+0.01*AK$3)) -> 0.94153056 | AL24: =AK24*(1-$AG24*(0.01+0.01*AL$3)) -> 0.92327193 | AM24: =AL24*(1-$AG24*(0.01+0.01*AM$3)) -> 0.90576669 | AN24: =AM24*(1-$AG24*(0.01+0.01*AN$3)) -> 0.88906662 | AO24: =AN24*(1-$AG24*(0.01+0.01*AO$3)) -> 0.87320567 | AP24: =AO24*(1-$AG24*(0.01+0.01*AP$3)) -> 0.85820182 | ... FC24: =FB24*(1-$AG24*(0.01+0.01*FC$3)) -> 0.25595353
A25: maint_pm_old = maint_pm_v1 * I_act(0) / I_act(-tau) (5.4) | B25: =inputs!$B$23*INDEX(I_act,MATCH(0,cpi_u,0))/INDEX(I_act,MATCH(-inputs!$B$14,cpi_u,0)) -> 5.16 | C25: used by OLD (5.4, C8) | F25: 43 | G25: =1-EXP(-inputs!$B$35-inputs!$B$36*inputs!$B$37^$F25*(inputs!$B$37-1)/LN(inputs!$B$37)) -> 0.00065624567 | H25: =1-EXP(-inputs!$B$35-inputs!$B$36*inputs!$B$37^($F25-4)*(inputs!$B$37-1)/LN(inputs!$B$37)) -> 0.00049332976 | I25: =0.96*G25 -> 0.00062999584 | J25: =0.96*H25 -> 0.00047359657 | L25: 23 | M25: =L25/12 -> 1.9166667 | N25: =0.04-0.015*EXP(-M25/10) -> 0.02761627 | O25: =EXP(-N25*M25) -> 0.94844528 | P25: =O25*EXP(-inputs!$B$27*L25/12) -> 0.93939943 | Q25: =0.045-0.015*EXP(-M25/10) -> 0.03261627 | R25: =EXP(-Q25*M25) -> 0.93939943 | S25: =R25*EXP(-inputs!$B$27*L25/12) -> 0.93043985 | T25: =INDEX(P_rec,MATCH(inputs!$B$13+L25,curve_t,0))/INDEX(P_rec,MATCH(inputs!$B$13,curve_t,0)) -> 0.93506377 | U25: =T25/T24 -> 0.99692284 | V25: =T24/T25-1 -> 0.0030866562 | X25: -1 | Y25: =IF(X25<=0,100*1.04^(X25/12),100*1.025^(X25/12)) -> 99.673694 | AA25: -3 | AB25: =IF(AA25<=-13,100*1.04^((AA25+12)/12),100.1*1.032^((AA25+12)/12)) -> 102.49292 | AC25: =AB25 -> 102.49292 | AD25: =AB25 -> 102.49292 | AF25: 41 | AG25: =IF($AF25<=85,1,IF($AF25<110,(110-$AF25)/25,0)) -> 1 | AH25: =1 -> 1 | AI25: =AH25*(1-$AG25*(0.01+0.01*AI$3)) -> 0.98 | AJ25: =AI25*(1-$AG25*(0.01+0.01*AJ$3)) -> 0.96047105 | AK25: =AJ25*(1-$AG25*(0.01+0.01*AK$3)) -> 0.94153056 | AL25: =AK25*(1-$AG25*(0.01+0.01*AL$3)) -> 0.92327193 | AM25: =AL25*(1-$AG25*(0.01+0.01*AM$3)) -> 0.90576669 | AN25: =AM25*(1-$AG25*(0.01+0.01*AN$3)) -> 0.88906662 | AO25: =AN25*(1-$AG25*(0.01+0.01*AO$3)) -> 0.87320567 | AP25: =AO25*(1-$AG25*(0.01+0.01*AP$3)) -> 0.85820182 | ... FC25: =FB25*(1-$AG25*(0.01+0.01*FC$3)) -> 0.25595353
A26: inv_expense: ie_rate | B26: 0.0015 | C26: Rate[Annual, Effective]; not stressed | F26: 44 | G26: =1-EXP(-inputs!$B$35-inputs!$B$36*inputs!$B$37^$F26*(inputs!$B$37-1)/LN(inputs!$B$37)) -> 0.00071032986 | H26: =1-EXP(-inputs!$B$35-inputs!$B$36*inputs!$B$37^($F26-4)*(inputs!$B$37-1)/LN(inputs!$B$37)) -> 0.00052722044 | I26: =0.96*G26 -> 0.00068191667 | J26: =0.96*H26 -> 0.00050613163 | L26: 24 | M26: =L26/12 -> 2 | N26: =0.04-0.015*EXP(-M26/10) -> 0.027719039 | O26: =EXP(-N26*M26) -> 0.94607061 | P26: =O26*EXP(-inputs!$B$27*L26/12) -> 0.93665705 | Q26: =0.045-0.015*EXP(-M26/10) -> 0.032719039 | R26: =EXP(-Q26*M26) -> 0.93665705 | S26: =R26*EXP(-inputs!$B$27*L26/12) -> 0.92733715 | T26: =INDEX(P_rec,MATCH(inputs!$B$13+L26,curve_t,0))/INDEX(P_rec,MATCH(inputs!$B$13,curve_t,0)) -> 0.93217404 | U26: =T26/T25 -> 0.99690959 | V26: =T25/T26-1 -> 0.0030999908 | X26: 0 | Y26: =IF(X26<=0,100*1.04^(X26/12),100*1.025^(X26/12)) -> 100 | AA26: -2 | AB26: =IF(AA26<=-13,100*1.04^((AA26+12)/12),100.1*1.032^((AA26+12)/12)) -> 102.7623 | AC26: =AB26 -> 102.7623 | AD26: =AB26 -> 102.7623 | AF26: 42 | AG26: =IF($AF26<=85,1,IF($AF26<110,(110-$AF26)/25,0)) -> 1 | AH26: =1 -> 1 | AI26: =AH26*(1-$AG26*(0.01+0.01*AI$3)) -> 0.98 | AJ26: =AI26*(1-$AG26*(0.01+0.01*AJ$3)) -> 0.96047105 | AK26: =AJ26*(1-$AG26*(0.01+0.01*AK$3)) -> 0.94153056 | AL26: =AK26*(1-$AG26*(0.01+0.01*AL$3)) -> 0.92327193 | AM26: =AL26*(1-$AG26*(0.01+0.01*AM$3)) -> 0.90576669 | AN26: =AM26*(1-$AG26*(0.01+0.01*AN$3)) -> 0.88906662 | AO26: =AN26*(1-$AG26*(0.01+0.01*AO$3)) -> 0.87320567 | AP26: =AO26*(1-$AG26*(0.01+0.01*AP$3)) -> 0.85820182 | ... FC26: =FB26*(1-$AG26*(0.01+0.01*FC$3)) -> 0.25595353
A27: ilp | B27: 0.005 | C27: Rate[Annual, Continuous]; part of the locked-in basis | F27: 45 | G27: =1-EXP(-inputs!$B$35-inputs!$B$36*inputs!$B$37^$F27*(inputs!$B$37-1)/LN(inputs!$B$37)) -> 0.00077111701 | H27: =1-EXP(-inputs!$B$35-inputs!$B$36*inputs!$B$37^($F27-4)*(inputs!$B$37-1)/LN(inputs!$B$37)) -> 0.0005653122 | I27: =0.96*G27 -> 0.00074027233 | J27: =0.96*H27 -> 0.00054269971 | L27: 25 | M27: =L27/12 -> 2.0833333 | N27: =0.04-0.015*EXP(-M27/10) -> 0.027820955 | O27: =EXP(-N27*M27) -> 0.94368739 | P27: =O27*EXP(-inputs!$B$27*L27/12) -> 0.93390833 | Q27: =0.045-0.015*EXP(-M27/10) -> 0.032820955 | R27: =EXP(-Q27*M27) -> 0.93390833 | S27: =R27*EXP(-inputs!$B$27*L27/12) -> 0.92423061 | T27: =INDEX(P_rec,MATCH(inputs!$B$13+L27,curve_t,0))/INDEX(P_rec,MATCH(inputs!$B$13,curve_t,0)) -> 0.92928105 | U27: =T27/T26 -> 0.99689651 | V27: =T26/T27-1 -> 0.0031131503 | X27: 1 | Y27: =IF(X27<=0,100*1.04^(X27/12),100*1.025^(X27/12)) -> 100.20598 | AA27: -1 | AB27: =IF(AA27<=-13,100*1.04^((AA27+12)/12),100.1*1.032^((AA27+12)/12)) -> 103.0324 | AC27: =AB27 -> 103.0324 | AD27: =AB27 -> 103.0324 | AF27: 43 | AG27: =IF($AF27<=85,1,IF($AF27<110,(110-$AF27)/25,0)) -> 1 | AH27: =1 -> 1 | AI27: =AH27*(1-$AG27*(0.01+0.01*AI$3)) -> 0.98 | AJ27: =AI27*(1-$AG27*(0.01+0.01*AJ$3)) -> 0.96047105 | AK27: =AJ27*(1-$AG27*(0.01+0.01*AK$3)) -> 0.94153056 | AL27: =AK27*(1-$AG27*(0.01+0.01*AL$3)) -> 0.92327193 | AM27: =AL27*(1-$AG27*(0.01+0.01*AM$3)) -> 0.90576669 | AN27: =AM27*(1-$AG27*(0.01+0.01*AN$3)) -> 0.88906662 | AO27: =AN27*(1-$AG27*(0.01+0.01*AO$3)) -> 0.87320567 | AP27: =AO27*(1-$AG27*(0.01+0.01*AP$3)) -> 0.85820182 | ... FC27: =FB27*(1-$AG27*(0.01+0.01*FC$3)) -> 0.25595353
A28: ra_param: alpha | B28: 0.75 | F28: 46 | G28: =1-EXP(-inputs!$B$35-inputs!$B$36*inputs!$B$37^$F28*(inputs!$B$37-1)/LN(inputs!$B$37)) -> 0.00083943734 | H28: =1-EXP(-inputs!$B$35-inputs!$B$36*inputs!$B$37^($F28-4)*(inputs!$B$37-1)/LN(inputs!$B$37)) -> 0.0006081256 | I28: =0.96*G28 -> 0.00080585985 | J28: =0.96*H28 -> 0.00058380057 | L28: 26 | M28: =L28/12 -> 2.1666667 | N28: =0.04-0.015*EXP(-M28/10) -> 0.027922025 | O28: =EXP(-N28*M28) -> 0.94129591 | P28: =O28*EXP(-inputs!$B$27*L28/12) -> 0.93115358 | Q28: =0.045-0.015*EXP(-M28/10) -> 0.032922025 | R28: =EXP(-Q28*M28) -> 0.93115358 | S28: =R28*EXP(-inputs!$B$27*L28/12) -> 0.92112053 | T28: =INDEX(P_rec,MATCH(inputs!$B$13+L28,curve_t,0))/INDEX(P_rec,MATCH(inputs!$B$13,curve_t,0)) -> 0.92638504 | U28: =T28/T27 -> 0.99688361 | V28: =T27/T28-1 -> 0.0031261369 | X28: 2 | Y28: =IF(X28<=0,100*1.04^(X28/12),100*1.025^(X28/12)) -> 100.41239 | AA28: 0 | AB28: =IF(AA28<=-13,100*1.04^((AA28+12)/12),100.1*1.032^((AA28+12)/12)) -> 103.3032 | AC28: =AB28 -> 103.3032 | AD28: =AB28 -> 103.3032 | AF28: 44 | AG28: =IF($AF28<=85,1,IF($AF28<110,(110-$AF28)/25,0)) -> 1 | AH28: =1 -> 1 | AI28: =AH28*(1-$AG28*(0.01+0.01*AI$3)) -> 0.98 | AJ28: =AI28*(1-$AG28*(0.01+0.01*AJ$3)) -> 0.96047105 | AK28: =AJ28*(1-$AG28*(0.01+0.01*AK$3)) -> 0.94153056 | AL28: =AK28*(1-$AG28*(0.01+0.01*AL$3)) -> 0.92327193 | AM28: =AL28*(1-$AG28*(0.01+0.01*AM$3)) -> 0.90576669 | AN28: =AM28*(1-$AG28*(0.01+0.01*AN$3)) -> 0.88906662 | AO28: =AN28*(1-$AG28*(0.01+0.01*AO$3)) -> 0.87320567 | AP28: =AO28*(1-$AG28*(0.01+0.01*AP$3)) -> 0.85820182 | ... FC28: =FB28*(1-$AG28*(0.01+0.01*FC$3)) -> 0.25595353
A29: ra_param: z_alpha | B29: 0.67448975 | F29: 47 | G29: =1-EXP(-inputs!$B$35-inputs!$B$36*inputs!$B$37^$F29*(inputs!$B$37-1)/LN(inputs!$B$37)) -> 0.00091622382 | H29: =1-EXP(-inputs!$B$35-inputs!$B$36*inputs!$B$37^($F29-4)*(inputs!$B$37-1)/LN(inputs!$B$37)) -> 0.00065624567 | I29: =0.96*G29 -> 0.00087957486 | J29: =0.96*H29 -> 0.00062999584 | L29: 27 | M29: =L29/12 -> 2.25 | N29: =0.04-0.015*EXP(-M29/10) -> 0.028022257 | O29: =EXP(-N29*M29) -> 0.93889645 | P29: =O29*EXP(-inputs!$B$27*L29/12) -> 0.92839306 | Q29: =0.045-0.015*EXP(-M29/10) -> 0.033022257 | R29: =EXP(-Q29*M29) -> 0.92839306 | S29: =R29*EXP(-inputs!$B$27*L29/12) -> 0.91800717 | T29: =INDEX(P_rec,MATCH(inputs!$B$13+L29,curve_t,0))/INDEX(P_rec,MATCH(inputs!$B$13,curve_t,0)) -> 0.92348626 | U29: =T29/T28 -> 0.99687087 | V29: =T28/T29-1 -> 0.0031389524 | X29: 3 | Y29: =IF(X29<=0,100*1.04^(X29/12),100*1.025^(X29/12)) -> 100.61922 | AA29: 1 | AC29: =$AB$28*INDEX(I_rec,MATCH(inputs!$B$13+AA29,cpi_rec_u,0))/INDEX(I_rec,MATCH(inputs!$B$13,cpi_rec_u,0)) -> 103.51599 | AD29: =$AB$28*1.03^(AA29/12) -> 103.55797 | AF29: 45 | AG29: =IF($AF29<=85,1,IF($AF29<110,(110-$AF29)/25,0)) -> 1 | AH29: =1 -> 1 | AI29: =AH29*(1-$AG29*(0.01+0.01*AI$3)) -> 0.98 | AJ29: =AI29*(1-$AG29*(0.01+0.01*AJ$3)) -> 0.96047105 | AK29: =AJ29*(1-$AG29*(0.01+0.01*AK$3)) -> 0.94153056 | AL29: =AK29*(1-$AG29*(0.01+0.01*AL$3)) -> 0.92327193 | AM29: =AL29*(1-$AG29*(0.01+0.01*AM$3)) -> 0.90576669 | AN29: =AM29*(1-$AG29*(0.01+0.01*AN$3)) -> 0.88906662 | AO29: =AN29*(1-$AG29*(0.01+0.01*AO$3)) -> 0.87320567 | AP29: =AO29*(1-$AG29*(0.01+0.01*AP$3)) -> 0.85820182 | ... FC29: =FB29*(1-$AG29*(0.01+0.01*FC$3)) -> 0.25595353
A30: ra_param: sigma_l | B30: 0.1 | F30: 48 | G30: =1-EXP(-inputs!$B$35-inputs!$B$36*inputs!$B$37^$F30*(inputs!$B$37-1)/LN(inputs!$B$37)) -> 0.0010025248 | H30: =1-EXP(-inputs!$B$35-inputs!$B$36*inputs!$B$37^($F30-4)*(inputs!$B$37-1)/LN(inputs!$B$37)) -> 0.00071032986 | I30: =0.96*G30 -> 0.00096242378 | J30: =0.96*H30 -> 0.00068191667 | L30: 28 | M30: =L30/12 -> 2.3333333 | N30: =0.04-0.015*EXP(-M30/10) -> 0.028121657 | O30: =EXP(-N30*M30) -> 0.93648929 | P30: =O30*EXP(-inputs!$B$27*L30/12) -> 0.92562706 | Q30: =0.045-0.015*EXP(-M30/10) -> 0.033121657 | R30: =EXP(-Q30*M30) -> 0.92562706 | S30: =R30*EXP(-inputs!$B$27*L30/12) -> 0.91489083 | T30: =INDEX(P_rec,MATCH(inputs!$B$13+L30,curve_t,0))/INDEX(P_rec,MATCH(inputs!$B$13,curve_t,0)) -> 0.92058495 | U30: =T30/T29 -> 0.9968583 | V30: =T29/T30-1 -> 0.0031515988 | X30: 4 | Y30: =IF(X30<=0,100*1.04^(X30/12),100*1.025^(X30/12)) -> 100.82648 | AA30: 2 | AC30: =$AB$28*INDEX(I_rec,MATCH(inputs!$B$13+AA30,cpi_rec_u,0))/INDEX(I_rec,MATCH(inputs!$B$13,cpi_rec_u,0)) -> 103.72921 | AD30: =$AB$28*1.03^(AA30/12) -> 103.81338 | AF30: 46 | AG30: =IF($AF30<=85,1,IF($AF30<110,(110-$AF30)/25,0)) -> 1 | AH30: =1 -> 1 | AI30: =AH30*(1-$AG30*(0.01+0.01*AI$3)) -> 0.98 | AJ30: =AI30*(1-$AG30*(0.01+0.01*AJ$3)) -> 0.96047105 | AK30: =AJ30*(1-$AG30*(0.01+0.01*AK$3)) -> 0.94153056 | AL30: =AK30*(1-$AG30*(0.01+0.01*AL$3)) -> 0.92327193 | AM30: =AL30*(1-$AG30*(0.01+0.01*AM$3)) -> 0.90576669 | AN30: =AM30*(1-$AG30*(0.01+0.01*AN$3)) -> 0.88906662 | AO30: =AN30*(1-$AG30*(0.01+0.01*AO$3)) -> 0.87320567 | AP30: =AO30*(1-$AG30*(0.01+0.01*AP$3)) -> 0.85820182 | ... FC30: =FB30*(1-$AG30*(0.01+0.01*FC$3)) -> 0.25595353
A31: ra_param: sigma_e | B31: 0.1 | F31: 49 | G31: =1-EXP(-inputs!$B$35-inputs!$B$36*inputs!$B$37^$F31*(inputs!$B$37-1)/LN(inputs!$B$37)) -> 0.0010995182 | H31: =1-EXP(-inputs!$B$35-inputs!$B$36*inputs!$B$37^($F31-4)*(inputs!$B$37-1)/LN(inputs!$B$37)) -> 0.00077111701 | I31: =0.96*G31 -> 0.0010555374 | J31: =0.96*H31 -> 0.00074027233 | L31: 29 | M31: =L31/12 -> 2.4166667 | N31: =0.04-0.015*EXP(-M31/10) -> 0.028220231 | O31: =EXP(-N31*M31) -> 0.93407467 | P31: =O31*EXP(-inputs!$B$27*L31/12) -> 0.92285586 | Q31: =0.045-0.015*EXP(-M31/10) -> 0.033220231 | R31: =EXP(-Q31*M31) -> 0.92285586 | S31: =R31*EXP(-inputs!$B$27*L31/12) -> 0.91177178 | T31: =INDEX(P_rec,MATCH(inputs!$B$13+L31,curve_t,0))/INDEX(P_rec,MATCH(inputs!$B$13,curve_t,0)) -> 0.91768133 | U31: =T31/T30 -> 0.9968459 | V31: =T30/T31-1 -> 0.0031640781 | X31: 5 | Y31: =IF(X31<=0,100*1.04^(X31/12),100*1.025^(X31/12)) -> 101.03417 | AA31: 3 | AC31: =$AB$28*INDEX(I_rec,MATCH(inputs!$B$13+AA31,cpi_rec_u,0))/INDEX(I_rec,MATCH(inputs!$B$13,cpi_rec_u,0)) -> 103.94288 | AD31: =$AB$28*1.03^(AA31/12) -> 104.06941 | AF31: 47 | AG31: =IF($AF31<=85,1,IF($AF31<110,(110-$AF31)/25,0)) -> 1 | AH31: =1 -> 1 | AI31: =AH31*(1-$AG31*(0.01+0.01*AI$3)) -> 0.98 | AJ31: =AI31*(1-$AG31*(0.01+0.01*AJ$3)) -> 0.96047105 | AK31: =AJ31*(1-$AG31*(0.01+0.01*AK$3)) -> 0.94153056 | AL31: =AK31*(1-$AG31*(0.01+0.01*AL$3)) -> 0.92327193 | AM31: =AL31*(1-$AG31*(0.01+0.01*AM$3)) -> 0.90576669 | AN31: =AM31*(1-$AG31*(0.01+0.01*AN$3)) -> 0.88906662 | AO31: =AN31*(1-$AG31*(0.01+0.01*AO$3)) -> 0.87320567 | AP31: =AO31*(1-$AG31*(0.01+0.01*AP$3)) -> 0.85820182 | ... FC31: =FB31*(1-$AG31*(0.01+0.01*FC$3)) -> 0.25595353
A32: ie_m = (1 + ie_rate)^(1/12) - 1 (6.4) | B32: =(1+inputs!$B$26)^(1/12)-1 -> 0.00012491414 | F32: 50 | G32: =1-EXP(-inputs!$B$35-inputs!$B$36*inputs!$B$37^$F32*(inputs!$B$37-1)/LN(inputs!$B$37)) -> 0.0012085275 | H32: =1-EXP(-inputs!$B$35-inputs!$B$36*inputs!$B$37^($F32-4)*(inputs!$B$37-1)/LN(inputs!$B$37)) -> 0.00083943734 | I32: =0.96*G32 -> 0.0011601864 | J32: =0.96*H32 -> 0.00080585985 | L32: 30 | M32: =L32/12 -> 2.5 | N32: =0.04-0.015*EXP(-M32/10) -> 0.028317988 | O32: =EXP(-N32*M32) -> 0.93165289 | P32: =O32*EXP(-inputs!$B$27*L32/12) -> 0.92007971 | Q32: =0.045-0.015*EXP(-M32/10) -> 0.033317988 | R32: =EXP(-Q32*M32) -> 0.92007971 | S32: =R32*EXP(-inputs!$B$27*L32/12) -> 0.9086503 | T32: =INDEX(P_rec,MATCH(inputs!$B$13+L32,curve_t,0))/INDEX(P_rec,MATCH(inputs!$B$13,curve_t,0)) -> 0.91477565 | U32: =T32/T31 -> 0.99683367 | V32: =T31/T32-1 -> 0.003176392 | X32: 6 | Y32: =IF(X32<=0,100*1.04^(X32/12),100*1.025^(X32/12)) -> 101.24228 | AA32: 4 | AC32: =$AB$28*INDEX(I_rec,MATCH(inputs!$B$13+AA32,cpi_rec_u,0))/INDEX(I_rec,MATCH(inputs!$B$13,cpi_rec_u,0)) -> 104.15698 | AD32: =$AB$28*1.03^(AA32/12) -> 104.32607 | AF32: 48 | AG32: =IF($AF32<=85,1,IF($AF32<110,(110-$AF32)/25,0)) -> 1 | AH32: =1 -> 1 | AI32: =AH32*(1-$AG32*(0.01+0.01*AI$3)) -> 0.98 | AJ32: =AI32*(1-$AG32*(0.01+0.01*AJ$3)) -> 0.96047105 | AK32: =AJ32*(1-$AG32*(0.01+0.01*AK$3)) -> 0.94153056 | AL32: =AK32*(1-$AG32*(0.01+0.01*AL$3)) -> 0.92327193 | AM32: =AL32*(1-$AG32*(0.01+0.01*AM$3)) -> 0.90576669 | AN32: =AM32*(1-$AG32*(0.01+0.01*AN$3)) -> 0.88906662 | AO32: =AN32*(1-$AG32*(0.01+0.01*AO$3)) -> 0.87320567 | AP32: =AO32*(1-$AG32*(0.01+0.01*AP$3)) -> 0.85820182 | ... FC32: =FB32*(1-$AG32*(0.01+0.01*FC$3)) -> 0.25595353
A33: mort_mult = exp(-sigma_l * z_alpha - sigma_l * sigma_l / 2) (6.8) | B33: =EXP(-inputs!$B$30*inputs!$B$29-inputs!$B$30*inputs!$B$30/2) -> 0.9301132 | F33: 51 | G33: =1-EXP(-inputs!$B$35-inputs!$B$36*inputs!$B$37^$F33*(inputs!$B$37-1)/LN(inputs!$B$37)) -> 0.0013310397 | H33: =1-EXP(-inputs!$B$35-inputs!$B$36*inputs!$B$37^($F33-4)*(inputs!$B$37-1)/LN(inputs!$B$37)) -> 0.00091622382 | I33: =0.96*G33 -> 0.0012777981 | J33: =0.96*H33 -> 0.00087957486 | L33: 31 | M33: =L33/12 -> 2.5833333 | N33: =0.04-0.015*EXP(-M33/10) -> 0.028414934 | O33: =EXP(-N33*M33) -> 0.92922419 | P33: =O33*EXP(-inputs!$B$27*L33/12) -> 0.91729889 | Q33: =0.045-0.015*EXP(-M33/10) -> 0.033414934 | R33: =EXP(-Q33*M33) -> 0.91729889 | S33: =R33*EXP(-inputs!$B$27*L33/12) -> 0.90552664 | T33: =INDEX(P_rec,MATCH(inputs!$B$13+L33,curve_t,0))/INDEX(P_rec,MATCH(inputs!$B$13,curve_t,0)) -> 0.91186812 | U33: =T33/T32 -> 0.99682159 | V33: =T32/T33-1 -> 0.0031885425 | X33: 7 | Y33: =IF(X33<=0,100*1.04^(X33/12),100*1.025^(X33/12)) -> 101.45083 | AA33: 5 | AC33: =$AB$28*INDEX(I_rec,MATCH(inputs!$B$13+AA33,cpi_rec_u,0))/INDEX(I_rec,MATCH(inputs!$B$13,cpi_rec_u,0)) -> 104.37153 | AD33: =$AB$28*1.03^(AA33/12) -> 104.58337 | AF33: 49 | AG33: =IF($AF33<=85,1,IF($AF33<110,(110-$AF33)/25,0)) -> 1 | AH33: =1 -> 1 | AI33: =AH33*(1-$AG33*(0.01+0.01*AI$3)) -> 0.98 | AJ33: =AI33*(1-$AG33*(0.01+0.01*AJ$3)) -> 0.96047105 | AK33: =AJ33*(1-$AG33*(0.01+0.01*AK$3)) -> 0.94153056 | AL33: =AK33*(1-$AG33*(0.01+0.01*AL$3)) -> 0.92327193 | AM33: =AL33*(1-$AG33*(0.01+0.01*AM$3)) -> 0.90576669 | AN33: =AM33*(1-$AG33*(0.01+0.01*AN$3)) -> 0.88906662 | AO33: =AN33*(1-$AG33*(0.01+0.01*AO$3)) -> 0.87320567 | AP33: =AO33*(1-$AG33*(0.01+0.01*AP$3)) -> 0.85820182 | ... FC33: =FB33*(1-$AG33*(0.01+0.01*FC$3)) -> 0.25595353
A34: exp_mult = exp(sigma_e * z_alpha - sigma_e * sigma_e / 2) (6.8) | B34: =EXP(inputs!$B$31*inputs!$B$29-inputs!$B$31*inputs!$B$31/2) -> 1.0644401 | F34: 52 | G34: =1-EXP(-inputs!$B$35-inputs!$B$36*inputs!$B$37^$F34*(inputs!$B$37-1)/LN(inputs!$B$37)) -> 0.0014687256 | H34: =1-EXP(-inputs!$B$35-inputs!$B$36*inputs!$B$37^($F34-4)*(inputs!$B$37-1)/LN(inputs!$B$37)) -> 0.0010025248 | I34: =0.96*G34 -> 0.0014099766 | J34: =0.96*H34 -> 0.00096242378 | L34: 32 | M34: =L34/12 -> 2.6666667 | N34: =0.04-0.015*EXP(-M34/10) -> 0.028511075 | O34: =EXP(-N34*M34) -> 0.92678884 | P34: =O34*EXP(-inputs!$B$27*L34/12) -> 0.91451367 | Q34: =0.045-0.015*EXP(-M34/10) -> 0.033511075 | R34: =EXP(-Q34*M34) -> 0.91451367 | S34: =R34*EXP(-inputs!$B$27*L34/12) -> 0.90240108 | T34: =INDEX(P_rec,MATCH(inputs!$B$13+L34,curve_t,0))/INDEX(P_rec,MATCH(inputs!$B$13,curve_t,0)) -> 0.90895897 | U34: =T34/T33 -> 0.99680968 | V34: =T33/T34-1 -> 0.0032005315 | X34: 8 | Y34: =IF(X34<=0,100*1.04^(X34/12),100*1.025^(X34/12)) -> 101.6598 | AA34: 6 | AC34: =$AB$28*INDEX(I_rec,MATCH(inputs!$B$13+AA34,cpi_rec_u,0))/INDEX(I_rec,MATCH(inputs!$B$13,cpi_rec_u,0)) -> 104.58652 | AD34: =$AB$28*1.03^(AA34/12) -> 104.8413 | AF34: 50 | AG34: =IF($AF34<=85,1,IF($AF34<110,(110-$AF34)/25,0)) -> 1 | AH34: =1 -> 1 | AI34: =AH34*(1-$AG34*(0.01+0.01*AI$3)) -> 0.98 | AJ34: =AI34*(1-$AG34*(0.01+0.01*AJ$3)) -> 0.96047105 | AK34: =AJ34*(1-$AG34*(0.01+0.01*AK$3)) -> 0.94153056 | AL34: =AK34*(1-$AG34*(0.01+0.01*AL$3)) -> 0.92327193 | AM34: =AL34*(1-$AG34*(0.01+0.01*AM$3)) -> 0.90576669 | AN34: =AM34*(1-$AG34*(0.01+0.01*AN$3)) -> 0.88906662 | AO34: =AN34*(1-$AG34*(0.01+0.01*AO$3)) -> 0.87320567 | AP34: =AO34*(1-$AG34*(0.01+0.01*AP$3)) -> 0.85820182 | ... FC34: =FB34*(1-$AG34*(0.01+0.01*FC$3)) -> 0.25595353
A35: Makeham A (6.1) | B35: 0.00022 | F35: 53 | G35: =1-EXP(-inputs!$B$35-inputs!$B$36*inputs!$B$37^$F35*(inputs!$B$37-1)/LN(inputs!$B$37)) -> 0.0016234618 | H35: =1-EXP(-inputs!$B$35-inputs!$B$36*inputs!$B$37^($F35-4)*(inputs!$B$37-1)/LN(inputs!$B$37)) -> 0.0010995182 | I35: =0.96*G35 -> 0.0015585234 | J35: =0.96*H35 -> 0.0010555374 | L35: 33 | M35: =L35/12 -> 2.75 | N35: =0.04-0.015*EXP(-M35/10) -> 0.028606418 | O35: =EXP(-N35*M35) -> 0.92434708 | P35: =O35*EXP(-inputs!$B$27*L35/12) -> 0.91172429 | Q35: =0.045-0.015*EXP(-M35/10) -> 0.033606418 | R35: =EXP(-Q35*M35) -> 0.91172429 | S35: =R35*EXP(-inputs!$B$27*L35/12) -> 0.89927387 | T35: =INDEX(P_rec,MATCH(inputs!$B$13+L35,curve_t,0))/INDEX(P_rec,MATCH(inputs!$B$13,curve_t,0)) -> 0.90604841 | U35: =T35/T34 -> 0.99679793 | V35: =T34/T35-1 -> 0.0032123608 | X35: 9 | Y35: =IF(X35<=0,100*1.04^(X35/12),100*1.025^(X35/12)) -> 101.8692 | AA35: 7 | AC35: =$AB$28*INDEX(I_rec,MATCH(inputs!$B$13+AA35,cpi_rec_u,0))/INDEX(I_rec,MATCH(inputs!$B$13,cpi_rec_u,0)) -> 104.80195 | AD35: =$AB$28*1.03^(AA35/12) -> 105.09986 | AF35: 51 | AG35: =IF($AF35<=85,1,IF($AF35<110,(110-$AF35)/25,0)) -> 1 | AH35: =1 -> 1 | AI35: =AH35*(1-$AG35*(0.01+0.01*AI$3)) -> 0.98 | AJ35: =AI35*(1-$AG35*(0.01+0.01*AJ$3)) -> 0.96047105 | AK35: =AJ35*(1-$AG35*(0.01+0.01*AK$3)) -> 0.94153056 | AL35: =AK35*(1-$AG35*(0.01+0.01*AL$3)) -> 0.92327193 | AM35: =AL35*(1-$AG35*(0.01+0.01*AM$3)) -> 0.90576669 | AN35: =AM35*(1-$AG35*(0.01+0.01*AN$3)) -> 0.88906662 | AO35: =AN35*(1-$AG35*(0.01+0.01*AO$3)) -> 0.87320567 | AP35: =AO35*(1-$AG35*(0.01+0.01*AP$3)) -> 0.85820182 | ... FC35: =FB35*(1-$AG35*(0.01+0.01*FC$3)) -> 0.25595353
